Workbook

Sheet General
A1: Food cost per 1k cal | B1: 5 | C1: $/ppm | D1: 100 | G1: Generic BU Level | H1: Generic BU Multiplier | I1: Generic AU Level | J1: Generic AU Multiplier | K1: Generic MU Level | L1: Generic MU Multiplier
A2: Min Wage $/1k | B2: 40 | C2: $/ppm-s | D2: =D1/3600 -> 0.027777778 | G2: 4 | H2: =SWITCH(G2, 0, 1, 1, 0.9,2,0.75,3,0.6,4,0.55,5,0.5) -> 0.55 | I2: 0 | J2: =SWITCH(I2, 0, 1, 1, 0.9,2,0.75,3,0.6,4,0.55,5,0.5) -> 1 | K2: 0 | L2: =SWITCH(K2, 0, 1, 1, 0.9,2,0.75,3,0.6,4,0.55,5,0.5) -> 1
A4: Skills | B4: Level | C4: Calorie Multiplier | D4: Food cost per 1k calories calc | E4: Min Wage calc | F4: Cost per 1k cal. | G4: BU Level | H4: BU Multi | I4: AU Level | J4: AU Multi | K4: MU Level | L4: MU Multi
A5: Carpentry | B5: 0 | C5: =IF(B5>0, 1-(0.15+B5*0.05), 1) -> 1 | D5: =$B$1 -> 5 | E5: =$B$2 -> 40 | F5: =IF(B5>0, D5*C5,E5) -> 40 | G5: =$G$2 -> 4 | H5: =SWITCH(G5, 0, 1, 1, 0.9,2,0.75,3,0.6,4,0.55,5,0.5)*IF(B5>=6, 0.95, 1) -> 0.55 | I5: =$I$2 -> 0 | J5: =SWITCH(I5, 0, 1, 1, 0.9,2,0.75,3,0.6,4,0.55,5,0.5)*IF(B5>=6, 0.95, 1) -> 1 | K5: =$K$2 -> 0 | L5: =SWITCH(K5, 0, 1, 1, 0.9,2,0.75,3,0.6,4,0.55,5,0.5)*IF(B5>=6, 0.95, 1) -> 1
A6: Logging | B6: 0 | C6: =IF(B6>0, 1-(0.15+B6*0.05), 1) -> 1 | D6: =$B$1 -> 5 | E6: =$B$2 -> 40 | F6: =IF(B6>0, D6*C6,E6) -> 40 | G6: =$G$2 -> 4 | H6: =SWITCH(G6, 0, 1, 1, 0.9,2,0.75,3,0.6,4,0.55,5,0.5) -> 0.55 | I6: =$I$2 -> 0 | J6: =SWITCH(I6, 0, 1, 1, 0.9,2,0.75,3,0.6,4,0.55,5,0.5) -> 1 | K6: =$K$2 -> 0 | L6: =SWITCH(K6, 0, 1, 1, 0.9,2,0.75,3,0.6,4,0.55,5,0.5) -> 1
A7: Composites | B7: 0 | C7: =IF(B7>0, 1-(0.15+B7*0.05), 1) -> 1 | D7: =$B$1 -> 5 | E7: =$B$2 -> 40 | F7: =IF(B7>0, D7*C7,E7) -> 40 | G7: =$G$2 -> 4 | H7: =SWITCH(G7, 0, 1, 1, 0.9,2,0.75,3,0.6,4,0.55,5,0.5)*IF(B7>=6, 0.95, 1) -> 0.55 | I7: =$I$2 -> 0 | J7: =SWITCH(I7, 0, 1, 1, 0.9,2,0.75,3,0.6,4,0.55,5,0.5)*IF(B7>=6, 0.95, 1) -> 1 | K7: =$K$2 -> 0 | L7: =SWITCH(K7, 0, 1, 1, 0.9,2,0.75,3,0.6,4,0.55,5,0.5)*IF(B7>=6, 0.95, 1) -> 1
A8: Paper Milling | B8: 0 | C8: =IF(B8>0, 1-(0.15+B8*0.05), 1) -> 1 | D8: =$B$1 -> 5 | E8: =$B$2 -> 40 | F8: =IF(B8>0, D8*C8,E8) -> 40 | G8: =$G$2 -> 4 | H8: =SWITCH(G8, 0, 1, 1, 0.9,2,0.75,3,0.6,4,0.55,5,0.5)*IF(B8>=6, 0.95, 1) -> 0.55 | I8: =$I$2 -> 0 | J8: =SWITCH(I8, 0, 1, 1, 0.9,2,0.75,3,0.6,4,0.55,5,0.5)*IF(B8>=6, 0.95, 1) -> 1 | K8: =$K$2 -> 0 | L8: =SWITCH(K8, 0, 1, 1, 0.9,2,0.75,3,0.6,4,0.55,5,0.5)*IF(B8>=6, 0.95, 1) -> 1
A9: Masonry | B9: 0 | C9: =IF(B9>0, 1-(0.15+B9*0.05), 1) -> 1 | D9: =$B$1 -> 5 | E9: =$B$2 -> 40 | F9: =IF(B9>0, D9*C9,E9) -> 40 | G9: =$G$2 -> 4 | H9: =SWITCH(G9, 0, 1, 1, 0.9,2,0.75,3,0.6,4,0.55,5,0.5)*IF(B9>=6, 0.95, 1) -> 0.55 | I9: =$I$2 -> 0 | J9: =SWITCH(I9, 0, 1, 1, 0.9,2,0.75,3,0.6,4,0.55,5,0.5)*IF(B9>=6, 0.95, 1) -> 1 | K9: =$K$2 -> 0 | L9: =SWITCH(K9, 0, 1, 1, 0.9,2,0.75,3,0.6,4,0.55,5,0.5)*IF(B9>=6, 0.95, 1) -> 1
A10: Mining | B10: 0 | C10: =IF(B10>0, 1-(0.15+B10*0.05), 1) -> 1 | D10: =$B$1 -> 5 | E10: =$B$2 -> 40 | F10: =IF(B10>0, D10*C10,E10) -> 40 | G10: =$G$2 -> 4 | H10: =SWITCH(G10, 0, 1, 1, 0.9,2,0.75,3,0.6,4,0.55,5,0.5) -> 0.55 | I10: =$I$2 -> 0 | J10: =SWITCH(I10, 0, 1, 1, 0.9,2,0.75,3,0.6,4,0.55,5,0.5)*IF(B10>=6, 0.95, 1) -> 1 | K10: =$K$2 -> 0 | L10: =SWITCH(K10, 0, 1, 1, 0.9,2,0.75,3,0.6,4,0.55,5,0.5) -> 1
A11: Advanced Masonry | B11: 0 | C11: =IF(B11>0, 1-(0.15+B11*0.05), 1) -> 1 | D11: =$B$1 -> 5 | E11: =$B$2 -> 40 | F11: =IF(B11>0, D11*C11,E11) -> 40 | G11: =$G$2 -> 4 | H11: =SWITCH(G11, 0, 1, 1, 0.9,2,0.75,3,0.6,4,0.55,5,0.5)*IF(B11>=6, 0.95, 1) -> 0.55 | I11: =$I$2 -> 0 | J11: =SWITCH(I11, 0, 1, 1, 0.9,2,0.75,3,0.6,4,0.55,5,0.5)*IF(B11>=6, 0.95, 1) -> 1 | K11: =$K$2 -> 0 | L11: =SWITCH(K11, 0, 1, 1, 0.9,2,0.75,3,0.6,4,0.55,5,0.5)*IF(B11>=6, 0.95, 1) -> 1
A12: Glassworking | B12: 0 | C12: =IF(B12>0, 1-(0.15+B12*0.05), 1) -> 1 | D12: =$B$1 -> 5 | E12: =$B$2 -> 40 | F12: =IF(B12>0, D12*C12,E12) -> 40 | G12: =$G$2 -> 4 | H12: =SWITCH(G12, 0, 1, 1, 0.9,2,0.75,3,0.6,4,0.55,5,0.5)*IF(B12>=6, 0.95, 1) -> 0.55 | I12: 5 | J12: =SWITCH(I12, 0, 1, 1, 0.9,2,0.75,3,0.6,4,0.55,5,0.5)*IF(B12>=6, 0.95, 1) -> 0.5 | K12: =$K$2 -> 0 | L12: =SWITCH(K12, 0, 1, 1, 0.9,2,0.75,3,0.6,4,0.55,5,0.5)*IF(B12>=6, 0.95, 1) -> 1
A13: Pottery | B13: 0 | C13: =IF(B13>0, 1-(0.15+B13*0.05), 1) -> 1 | D13: =$B$1 -> 5 | E13: =$B$2 -> 40 | F13: =IF(B13>0, D13*C13,E13) -> 40 | G13: =$G$2 -> 4 | H13: =SWITCH(G13, 0, 1, 1, 0.9,2,0.75,3,0.6,4,0.55,5,0.5)*IF(B13>=6, 0.95, 1) -> 0.55 | I13: =$I$2 -> 0 | J13: =SWITCH(I13, 0, 1, 1, 0.9,2,0.75,3,0.6,4,0.55,5,0.5)*IF(B13>=6, 0.95, 1) -> 1 | K13: =$K$2 -> 0 | L13: =SWITCH(K13, 0, 1, 1, 0.9,2,0.75,3,0.6,4,0.55,5,0.5)*IF(B13>=6, 0.95, 1) -> 1
A14: Campfire Cooking | B14: 0 | C14: =IF(B14>0, 1-(0.15+B14*0.05), 1) -> 1 | D14: =$B$1 -> 5 | E14: =$B$2 -> 40 | F14: =IF(B14>0, D14*C14,E14) -> 40 | G14: =$G$2 -> 4 | H14: =SWITCH(G14, 0, 1, 1, 0.9,2,0.75,3,0.6,4,0.55,5,0.5)*IF(B14>=6, 0.95, 1) -> 0.55 | I14: =$I$2 -> 0 | J14: =SWITCH(I14, 0, 1, 1, 0.9,2,0.75,3,0.6,4,0.55,5,0.5)*IF(B14>=6, 0.95, 1) -> 1 | K14: =$K$2 -> 0 | L14: =SWITCH(K14, 0, 1, 1, 0.9,2,0.75,3,0.6,4,0.55,5,0.5)*IF(B14>=6, 0.95, 1) -> 1
A15: Advanced Baking | B15: 0 | C15: =IF(B15>0, 1-(0.15+B15*0.05), 1) -> 1 | D15: =$B$1 -> 5 | E15: =$B$2 -> 40 | F15: =IF(B15>0, D15*C15,E15) -> 40 | G15: =$G$2 -> 4 | H15: =SWITCH(G15, 0, 1, 1, 0.9,2,0.75,3,0.6,4,0.55,5,0.5)*IF(B15>=6, 0.95, 1) -> 0.55 | I15: =$I$2 -> 0 | J15: =SWITCH(I15, 0, 1, 1, 0.9,2,0.75,3,0.6,4,0.55,5,0.5)*IF(B15>=6, 0.95, 1) -> 1 | K15: =$K$2 -> 0 | L15: =SWITCH(K15, 0, 1, 1, 0.9,2,0.75,3,0.6,4,0.55,5,0.5)*IF(B15>=6, 0.95, 1) -> 1
A16: Advanced Cooking | B16: 0 | C16: =IF(B16>0, 1-(0.15+B16*0.05), 1) -> 1 | D16: =$B$1 -> 5 | E16: =$B$2 -> 40 | F16: =IF(B16>0, D16*C16,E16) -> 40 | G16: =$G$2 -> 4 | H16: =SWITCH(G16, 0, 1, 1, 0.9,2,0.75,3,0.6,4,0.55,5,0.5)*IF(B16>=6, 0.95, 1) -> 0.55 | I16: =$I$2 -> 0 | J16: =SWITCH(I16, 0, 1, 1, 0.9,2,0.75,3,0.6,4,0.55,5,0.5)*IF(B16>=6, 0.95, 1) -> 1 | K16: =$K$2 -> 0 | L16: =SWITCH(K16, 0, 1, 1, 0.9,2,0.75,3,0.6,4,0.55,5,0.5)*IF(B16>=6, 0.95, 1) -> 1
A17: Baking | B17: 0 | C17: =IF(B17>0, 1-(0.15+B17*0.05), 1) -> 1 | D17: =$B$1 -> 5 | E17: =$B$2 -> 40 | F17: =IF(B17>0, D17*C17,E17) -> 40 | G17: =$G$2 -> 4 | H17: =SWITCH(G17, 0, 1, 1, 0.9,2,0.75,3,0.6,4,0.55,5,0.5)*IF(B17>=6, 0.95, 1) -> 0.55 | I17: =$I$2 -> 0 | J17: =SWITCH(I17, 0, 1, 1, 0.9,2,0.75,3,0.6,4,0.55,5,0.5)*IF(B17>=6, 0.95, 1) -> 1 | K17: =$K$2 -> 0 | L17: =SWITCH(K17, 0, 1, 1, 0.9,2,0.75,3,0.6,4,0.55,5,0.5)*IF(B17>=6, 0.95, 1) -> 1
A18: Cooking | B18: 0 | C18: =IF(B18>0, 1-(0.15+B18*0.05), 1) -> 1 | D18: =$B$1 -> 5 | E18: =$B$2 -> 40 | F18: =IF(B18>0, D18*C18,E18) -> 40 | G18: =$G$2 -> 4 | H18: =SWITCH(G18, 0, 1, 1, 0.9,2,0.75,3,0.6,4,0.55,5,0.5)*IF(B18>=6, 0.95, 1) -> 0.55 | I18: =$I$2 -> 0 | J18: =SWITCH(I18, 0, 1, 1, 0.9,2,0.75,3,0.6,4,0.55,5,0.5)*IF(B18>=6, 0.95, 1) -> 1 | K18: =$K$2 -> 0 | L18: =SWITCH(K18, 0, 1, 1, 0.9,2,0.75,3,0.6,4,0.55,5,0.5)*IF(B18>=6, 0.95, 1) -> 1
A19: Basic Engineering | B19: 0 | C19: =IF(B19>0, 1-(0.15+B19*0.05), 1) -> 1 | D19: =$B$1 -> 5 | E19: =$B$2 -> 40 | F19: =IF(B19>0, D19*C19,E19) -> 40 | G19: =$G$2 -> 4 | H19: =SWITCH(G19, 0, 1, 1, 0.9,2,0.75,3,0.6,4,0.55,5,0.5)*IF(B19>=6, 0.95, 1) -> 0.55 | I19: =$I$2 -> 0 | J19: =SWITCH(I19, 0, 1, 1, 0.9,2,0.75,3,0.6,4,0.55,5,0.5)*IF(B19>=6, 0.95, 1) -> 1 | K19: =$K$2 -> 0 | L19: =SWITCH(K19, 0, 1, 1, 0.9,2,0.75,3,0.6,4,0.55,5,0.5)*IF(B19>=6, 0.95, 1) -> 1
A20: Electronics | B20: 0 | C20: =IF(B20>0, 1-(0.15+B20*0.05), 1) -> 1 | D20: =$B$1 -> 5 | E20: =$B$2 -> 40 | F20: =IF(B20>0, D20*C20,E20) -> 40 | G20: =$G$2 -> 4 | H20: =SWITCH(G20, 0, 1, 1, 0.9,2,0.75,3,0.6,4,0.55,5,0.5)*IF(B20>=6, 0.95, 1) -> 0.55 | I20: =$I$2 -> 0 | J20: =SWITCH(I20, 0, 1, 1, 0.9,2,0.75,3,0.6,4,0.55,5,0.5)*IF(B20>=6, 0.95, 1) -> 1 | K20: =$K$2 -> 0 | L20: =SWITCH(K20, 0, 1, 1, 0.9,2,0.75,3,0.6,4,0.55,5,0.5)*IF(B20>=6, 0.95, 1) -> 1
A21: Industry | B21: 0 | C21: =IF(B21>0, 1-(0.15+B21*0.05), 1) -> 1 | D21: =$B$1 -> 5 | E21: =$B$2 -> 40 | F21: =IF(B21>0, D21*C21,E21) -> 40 | G21: =$G$2 -> 4 | H21: =SWITCH(G21, 0, 1, 1, 0.9,2,0.75,3,0.6,4,0.55,5,0.5)*IF(B21>=6, 0.95, 1) -> 0.55 | I21: =$I$2 -> 0 | J21: =SWITCH(I21, 0, 1, 1, 0.9,2,0.75,3,0.6,4,0.55,5,0.5)*IF(B21>=6, 0.95, 1) -> 1 | K21: =$K$2 -> 0 | L21: =SWITCH(K21, 0, 1, 1, 0.9,2,0.75,3,0.6,4,0.55,5,0.5)*IF(B21>=6, 0.95, 1) -> 1
A22: Mechanics | B22: 0 | C22: =IF(B22>0, 1-(0.15+B22*0.05), 1) -> 1 | D22: =$B$1 -> 5 | E22: =$B$2 -> 40 | F22: =IF(B22>0, D22*C22,E22) -> 40 | G22: =$G$2 -> 4 | H22: =SWITCH(G22, 0, 1, 1, 0.9,2,0.75,3,0.6,4,0.55,5,0.5)*IF(B22>=6, 0.95, 1) -> 0.55 | I22: =$I$2 -> 0 | J22: =SWITCH(I22, 0, 1, 1, 0.9,2,0.75,3,0.6,4,0.55,5,0.5)*IF(B22>=6, 0.95, 1) -> 1 | K22: =$K$2 -> 0 | L22: =SWITCH(K22, 0, 1, 1, 0.9,2,0.75,3,0.6,4,0.55,5,0.5)*IF(B22>=6, 0.95, 1) -> 1
A23: Oil Drilling | B23: 0 | C23: =IF(B23>0, 1-(0.15+B23*0.05), 1) -> 1 | D23: =$B$1 -> 5 | E23: =$B$2 -> 40 | F23: =IF(B23>0, D23*C23,E23) -> 40 | G23: =$G$2 -> 4 | H23: =SWITCH(G23, 0, 1, 1, 0.9,2,0.75,3,0.6,4,0.55,5,0.5)*IF(B23>=6, 0.95, 1) -> 0.55 | I23: =$I$2 -> 0 | J23: =SWITCH(I23, 0, 1, 1, 0.9,2,0.75,3,0.6,4,0.55,5,0.5)*IF(B23>=6, 0.95, 1) -> 1 | K23: =$K$2 -> 0 | L23: =SWITCH(K23, 0, 1, 1, 0.9,2,0.75,3,0.6,4,0.55,5,0.5)*IF(B23>=6, 0.95, 1) -> 1
A24: Farming | B24: 0 | C24: =IF(B24>0, 1-(0.15+B24*0.05), 1) -> 1 | D24: =$B$1 -> 5 | E24: =$B$2 -> 40 | F24: =IF(B24>0, D24*C24,E24) -> 40 | G24: =$G$2 -> 4 | H24: =SWITCH(G24, 0, 1, 1, 0.9,2,0.75,3,0.6,4,0.55,5,0.5)*IF(B24>=6, 0.95, 1) -> 0.55 | I24: =$I$2 -> 0 | J24: =SWITCH(I24, 0, 1, 1, 0.9,2,0.75,3,0.6,4,0.55,5,0.5)*IF(B24>=6, 0.95, 1) -> 1 | K24: =$K$2 -> 0 | L24: =SWITCH(K24, 0, 1, 1, 0.9,2,0.75,3,0.6,4,0.55,5,0.5)*IF(B24>=6, 0.95, 1) -> 1
... A26: Fertilizers | B26: 0 | C26: =IF(B26>0, 1-(0.15+B26*0.05), 1) -> 1 | D26: =$B$1 -> 5 | E26: =$B$2 -> 40 | F26: =IF(B26>0, D26*C26,E26) -> 40 | G26: =$G$2 -> 4 | H26: =SWITCH(G26, 0, 1, 1, 0.9,2,0.75,3,0.6,4,0.55,5,0.5)*IF(B26>=6, 0.95, 1) -> 0.55 | I26: =$I$2 -> 0 | J26: =SWITCH(I26, 0, 1, 1, 0.9,2,0.75,3,0.6,4,0.55,5,0.5)*IF(B26>=6, 0.95, 1) -> 1 | K26: =$K$2 -> 0 | L26: =SWITCH(K26, 0, 1, 1, 0.9,2,0.75,3,0.6,4,0.55,5,0.5)*IF(B26>=6, 0.95, 1) -> 1
A27: Milling | B27: 7 | C27: =IF(B27>0, 1-(0.15+B27*0.05), 1) -> 0.5 | D27: =$B$1 -> 5 | E27: =$B$2 -> 40 | F27: =IF(B27>0, D27*C27,E27) -> 2.5 | G27: 5 | H27: =SWITCH(G27, 0, 1, 1, 0.9,2,0.75,3,0.6,4,0.55,5,0.5)*IF(B27>=6, 0.95, 1) -> 0.475 | I27: =$I$2 -> 0 | J27: =SWITCH(I27, 0, 1, 1, 0.9,2,0.75,3,0.6,4,0.55,5,0.5)*IF(B27>=6, 0.95, 1) -> 0.95 | K27: =$K$2 -> 0 | L27: =SWITCH(K27, 0, 1, 1, 0.9,2,0.75,3,0.6,4,0.55,5,0.5)*IF(B27>=6, 0.95, 1) -> 0.95
A28: Butchery | B28: 0 | C28: =IF(B28>0, 1-(0.15+B28*0.05), 1) -> 1 | D28: =$B$1 -> 5 | E28: =$B$2 -> 40 | F28: =IF(B28>0, D28*C28,E28) -> 40 | G28: =$G$2 -> 4 | H28: =SWITCH(G28, 0, 1, 1, 0.9,2,0.75,3,0.6,4,0.55,5,0.5)*IF(B28>=6, 0.95, 1) -> 0.55 | I28: =$I$2 -> 0 | J28: =SWITCH(I28, 0, 1, 1, 0.9,2,0.75,3,0.6,4,0.55,5,0.5)*IF(B28>=6, 0.95, 1) -> 1 | K28: =$K$2 -> 0 | L28: =SWITCH(K28, 0, 1, 1, 0.9,2,0.75,3,0.6,4,0.55,5,0.5)*IF(B28>=6, 0.95, 1) -> 1
A29: Hunting | B29: 0 | C29: =IF(B29>0, 1-(0.15+B29*0.05), 1) -> 1 | D29: =$B$1 -> 5 | E29: =$B$2 -> 40 | F29: =IF(B29>0, D29*C29,E29) -> 40 | G29: =$G$2 -> 4 | H29: =SWITCH(G29, 0, 1, 1, 0.9,2,0.75,3,0.6,4,0.55,5,0.5)*IF(B29>=6, 0.95, 1) -> 0.55 | I29: =$I$2 -> 0 | J29: =SWITCH(I29, 0, 1, 1, 0.9,2,0.75,3,0.6,4,0.55,5,0.5)*IF(B29>=6, 0.95, 1) -> 1 | K29: =$K$2 -> 0 | L29: =SWITCH(K29, 0, 1, 1, 0.9,2,0.75,3,0.6,4,0.55,5,0.5)*IF(B29>=6, 0.95, 1) -> 1
A30: Smelting | B30: 0 | C30: =IF(B30>0, 1-(0.15+B30*0.05), 1) -> 1 | D30: =$B$1 -> 5 | E30: =$B$2 -> 40 | F30: =IF(B30>0, D30*C30,E30) -> 40 | G30: =$G$2 -> 4 | H30: =SWITCH(G30, 0, 1, 1, 0.9,2,0.75,3,0.6,4,0.55,5,0.5)*IF(B30>=6, 0.95, 1) -> 0.55 | I30: =$I$2 -> 0 | J30: =SWITCH(I30, 0, 1, 1, 0.9,2,0.75,3,0.6,4,0.55,5,0.5)*IF(B30>=6, 0.95, 1) -> 1 | K30: =$K$2 -> 0 | L30: =SWITCH(K30, 0, 1, 1, 0.9,2,0.75,3,0.6,4,0.55,5,0.5)*IF(B30>=6, 0.95, 1) -> 1
A31: Advanced Smelting | B31: 0 | C31: =IF(B31>0, 1-(0.15+B31*0.05), 1) -> 1 | D31: =$B$1 -> 5 | E31: =$B$2 -> 40 | F31: =IF(B31>0, D31*C31,E31) -> 40 | G31: =$G$2 -> 4 | H31: =SWITCH(G31, 0, 1, 1, 0.9,2,0.75,3,0.6,4,0.55,5,0.5)*IF(B31>=6, 0.95, 1) -> 0.55 | I31: =$I$2 -> 0 | J31: =SWITCH(I31, 0, 1, 1, 0.9,2,0.75,3,0.6,4,0.55,5,0.5)*IF(B31>=6, 0.95, 1) -> 1 | K31: =$K$2 -> 0 | L31: =SWITCH(K31, 0, 1, 1, 0.9,2,0.75,3,0.6,4,0.55,5,0.5)*IF(B31>=6, 0.95, 1) -> 1
A32: Shipwright | B32: 0 | C32: =IF(B32>0, 1-(0.15+B32*0.05), 1) -> 1 | D32: =$B$1 -> 5 | E32: =$B$2 -> 40 | F32: =IF(B32>0, D32*C32,E32) -> 40 | G32: =$G$2 -> 4 | H32: =SWITCH(G32, 0, 1, 1, 0.9,2,0.75,3,0.6,4,0.55,5,0.5)*IF(B32>=6, 0.95, 1) -> 0.55 | I32: =$I$2 -> 0 | J32: =SWITCH(I32, 0, 1, 1, 0.9,2,0.75,3,0.6,4,0.55,5,0.5)*IF(B32>=6, 0.95, 1) -> 1 | K32: =$K$2 -> 0 | L32: =SWITCH(K32, 0, 1, 1, 0.9,2,0.75,3,0.6,4,0.55,5,0.5)*IF(B32>=6, 0.95, 1) -> 1
A33: Painting | B33: 3 | C33: =IF(B33>0, 1-(0.15+B33*0.05), 1) -> 0.7 | D33: =$B$1 -> 5 | E33: =$B$2 -> 40 | F33: =IF(B33>0, D33*C33,E33) -> 3.5 | G33: =$G$2 -> 4 | H33: =SWITCH(G33, 0, 1, 1, 0.9,2,0.75,3,0.6,4,0.55,5,0.5)*IF(B33>=6, 0.95, 1) -> 0.55 | I33: =$I$2 -> 0 | J33: =SWITCH(I33, 0, 1, 1, 0.9,2,0.75,3,0.6,4,0.55,5,0.5)*IF(B33>=6, 0.95, 1) -> 1 | K33: =$K$2 -> 0 | L33: =SWITCH(K33, 0, 1, 1, 0.9,2,0.75,3,0.6,4,0.55,5,0.5)*IF(B33>=6, 0.95, 1) -> 1
A34: None | B34: 0 | C34: =IF(B34>0, 1-(0.15+B34*0.05), 1) -> 1 | D34: =$B$1 -> 5 | E34: =$B$2 -> 40 | F34: =IF(B34>0, D34*C34,E34) -> 40 | G34: =$G$2 -> 4 | H34: =SWITCH(G34, 0, 1, 1, 0.9,2,0.75,3,0.6,4,0.55,5,0.5)*IF(B34>=6, 0.95, 1) -> 0.55 | I34: =$I$2 -> 0 | J34: =SWITCH(I34, 0, 1, 1, 0.9,2,0.75,3,0.6,4,0.55,5,0.5)*IF(B34>=6, 0.95, 1) -> 1 | K34: =$K$2 -> 0 | L34: =SWITCH(K34, 0, 1, 1, 0.9,2,0.75,3,0.6,4,0.55,5,0.5)*IF(B34>=6, 0.95, 1) -> 1
A35: Tailoring | B35: 0 | C35: =IF(B35>0, 1-(0.15+B35*0.05), 1) -> 1 | D35: =$B$1 -> 5 | E35: =$B$2 -> 40 | F35: =IF(B35>0, D35*C35,E35) -> 40 | G35: =$G$2 -> 4 | H35: =SWITCH(G35, 0, 1, 1, 0.9,2,0.75,3,0.6,4,0.55,5,0.5)*IF(B35>=6, 0.95, 1) -> 0.55 | I35: =$I$2 -> 0 | J35: =SWITCH(I35, 0, 1, 1, 0.9,2,0.75,3,0.6,4,0.55,5,0.5)*IF(B35>=6, 0.95, 1) -> 1 | K35: =$K$2 -> 0 | L35: =SWITCH(K35, 0, 1, 1, 0.9,2,0.75,3,0.6,4,0.55,5,0.5)*IF(B35>=6, 0.95, 1) -> 1
A39: Burnables | B39: Price | C39: Joules | D39: $/J
A40: Charcoal | B40: 1.2 | C40: 20000 | D40: =B40/C40 -> 6e-05
A41: Crushed Coal | B41: 3 | C41: 80000 | D41: =B41/C41 -> 3.75e-05
A42: Cheapest | D42: =MIN(D40:D41) -> 3.75e-05
A44: Electricity | B44: Watts Produced | C44: Watts Consumed | D44: $/s | E44: $/w Electric | F44: PPM/h
A45: Combustion Generator | B45: 3000 | C45: 0 | D45: =$D$42*C45 -> 0 | E45: =D45/B45 -> 0 | F45: 1.12

Sheet Shop 1 Prices
A1: Selling | B1: Total Markup: | C1: =(1+G1)*(1/(1-$E$1)) -> 1.875 | D1: Tax | E1: 0.2 | F1: Markup: | G1: 0.5 | I1: Buying | J1: Markup: | K1: 0.8
A2: Item | B2: Shop Price | C2: Flat Addition | D2: Individual Markup | E2: Override? | F2: Cost Override | G2: Cost | H2: Test | I2: Item | J2: Shop Price | K2: Individual Markup | L2: Override? | M2: Cost Override | N2: Cost
A3: Basic Upgrade 1 | B3: =IF(ISBLANK(A3),"", IFERROR(IF(E3, F3, G3) * IF(ISBLANK(D3), C$1,D3) + C3, "")) -> 129.375 | E3: FALSE | G3: =IFERROR(VLOOKUP(A3, 'Price Sheet'!$A$2:$B1010, 2, false), "") -> 69 | I3: Wood (Tag) | J3: =IF(ISBLANK(I3),"", IFERROR(IF(L3, M3, N3) * IF(ISBLANK(K3), K$1,K3), "")) -> 0.4 | L3: FALSE | N3: =IFERROR(VLOOKUP(I3, 'Price Sheet'!$A$2:$B1010, 2, false), "") -> 0.5
A4: Basic Upgrade 2 | B4: =IF(ISBLANK(A4),"", IFERROR(IF(E4, F4, G4) * IF(ISBLANK(D4), C$1,D4) + C4, "")) -> 238.125 | E4: FALSE | G4: =IFERROR(VLOOKUP(A4, 'Price Sheet'!$A$2:$B1010, 2, false), "") -> 127 | J4: =IF(ISBLANK(I4),"", IFERROR(IF(L4, M4, N4) * IF(ISBLANK(K4), K$1,K4), "")) | L4: FALSE | N4: =IFERROR(VLOOKUP(I4, 'Price Sheet'!$A$2:$B1010, 2, false), "")
A5: Basic Upgrade 3 | B5: =IF(ISBLANK(A5),"", IFERROR(IF(E5, F5, G5) * IF(ISBLANK(D5), C$1,D5) + C5, "")) -> 871.875 | E5: FALSE | G5: =IFERROR(VLOOKUP(A5, 'Price Sheet'!$A$2:$B1010, 2, false), "") -> 465 | J5: =IF(ISBLANK(I5),"", IFERROR(IF(L5, M5, N5) * IF(ISBLANK(K5), K$1,K5), "")) | L5: FALSE | N5: =IFERROR(VLOOKUP(I5, 'Price Sheet'!$A$2:$B1010, 2, false), "")
A6: Basic Upgrade 4 | B6: =IF(ISBLANK(A6),"", IFERROR(IF(E6, F6, G6) * IF(ISBLANK(D6), C$1,D6) + C6, "")) -> 1229.1562 | E6: FALSE | G6: =IFERROR(VLOOKUP(A6, 'Price Sheet'!$A$2:$B1010, 2, false), "") -> 655.55 | J6: =IF(ISBLANK(I6),"", IFERROR(IF(L6, M6, N6) * IF(ISBLANK(K6), K$1,K6), "")) | L6: FALSE | N6: =IFERROR(VLOOKUP(I6, 'Price Sheet'!$A$2:$B1010, 2, false), "")
B7: =IF(ISBLANK(A7),"", IFERROR(IF(E7, F7, G7) * IF(ISBLANK(D7), C$1,D7) + C7, "")) | E7: FALSE | G7: =IFERROR(VLOOKUP(A7, 'Price Sheet'!$A$2:$B1010, 2, false), "") | J7: =IF(ISBLANK(I7),"", IFERROR(IF(L7, M7, N7) * IF(ISBLANK(K7), K$1,K7), "")) | L7: FALSE | N7: =IFERROR(VLOOKUP(I7, 'Price Sheet'!$A$2:$B1010, 2, false), "")
A8: Blue Powder | B8: =IF(ISBLANK(A8),"", IFERROR(IF(E8, F8, G8) * IF(ISBLANK(D8), C$1,D8) + C8, "")) -> 0.04921875 | E8: FALSE | G8: =IFERROR(VLOOKUP(A8, 'Price Sheet'!$A$2:$B1010, 2, false), "") -> 0.02625 | J8: =IF(ISBLANK(I8),"", IFERROR(IF(L8, M8, N8) * IF(ISBLANK(K8), K$1,K8), "")) | L8: FALSE | N8: =IFERROR(VLOOKUP(I8, 'Price Sheet'!$A$2:$B1010, 2, false), "")
A9: Colored Powder | B9: =IF(ISBLANK(A9),"", IFERROR(IF(E9, F9, G9) * IF(ISBLANK(D9), C$1,D9) + C9, "")) -> 0.46875 | E9: FALSE | G9: =IFERROR(VLOOKUP(A9, 'Price Sheet'!$A$2:$B1010, 2, false), "") -> 0.25 | J9: =IF(ISBLANK(I9),"", IFERROR(IF(L9, M9, N9) * IF(ISBLANK(K9), K$1,K9), "")) | L9: FALSE | N9: =IFERROR(VLOOKUP(I9, 'Price Sheet'!$A$2:$B1010, 2, false), "")
A10: Copper Hydroxide | B10: =IF(ISBLANK(A10),"", IFERROR(IF(E10, F10, G10) * IF(ISBLANK(D10), C$1,D10) + C10, "")) -> 0.38046875 | E10: FALSE | G10: =IFERROR(VLOOKUP(A10, 'Price Sheet'!$A$2:$B1010, 2, false), "") -> 0.20291667 | J10: =IF(ISBLANK(I10),"", IFERROR(IF(L10, M10, N10) * IF(ISBLANK(K10), K$1,K10), "")) | L10: FALSE | N10: =IFERROR(VLOOKUP(I10, 'Price Sheet'!$A$2:$B1010, 2, false), "")
A11: Cyan Powder | B11: =IF(ISBLANK(A11),"", IFERROR(IF(E11, F11, G11) * IF(ISBLANK(D11), C$1,D11) + C11, "")) -> 0.18633333 | E11: FALSE | G11: =IFERROR(VLOOKUP(A11, 'Price Sheet'!$A$2:$B1010, 2, false), "") -> 0.099377778 | J11: =IF(ISBLANK(I11),"", IFERROR(IF(L11, M11, N11) * IF(ISBLANK(K11), K$1,K11), "")) | L11: FALSE | N11: =IFERROR(VLOOKUP(I11, 'Price Sheet'!$A$2:$B1010, 2, false), "")
A12: Iron Oxide | B12: =IF(ISBLANK(A12),"", IFERROR(IF(E12, F12, G12) * IF(ISBLANK(D12), C$1,D12) + C12, "")) -> 0.29238281 | E12: FALSE | G12: =IFERROR(VLOOKUP(A12, 'Price Sheet'!$A$2:$B1010, 2, false), "") -> 0.1559375 | J12: =IF(ISBLANK(I12),"", IFERROR(IF(L12, M12, N12) * IF(ISBLANK(K12), K$1,K12), "")) | L12: FALSE | N12: =IFERROR(VLOOKUP(I12, 'Price Sheet'!$A$2:$B1010, 2, false), "")
A13: Charcoal Powder | B13: =IF(ISBLANK(A13),"", IFERROR(IF(E13, F13, G13) * IF(ISBLANK(D13), C$1,D13) + C13, "")) -> 0.200625 | E13: FALSE | G13: =IFERROR(VLOOKUP(A13, 'Price Sheet'!$A$2:$B1010, 2, false), "") -> 0.107 | J13: =IF(ISBLANK(I13),"", IFERROR(IF(L13, M13, N13) * IF(ISBLANK(K13), K$1,K13), "")) | L13: FALSE | N13: =IFERROR(VLOOKUP(I13, 'Price Sheet'!$A$2:$B1010, 2, false), "")
A14: Magenta Powder | B14: =IF(ISBLANK(A14),"", IFERROR(IF(E14, F14, G14) * IF(ISBLANK(D14), C$1,D14) + C14, "")) -> 0.200625 | E14: FALSE | G14: =IFERROR(VLOOKUP(A14, 'Price Sheet'!$A$2:$B1010, 2, false), "") -> 0.107 | J14: =IF(ISBLANK(I14),"", IFERROR(IF(L14, M14, N14) * IF(ISBLANK(K14), K$1,K14), "")) | L14: FALSE | N14: =IFERROR(VLOOKUP(I14, 'Price Sheet'!$A$2:$B1010, 2, false), "")
A15: White Powder | B15: =IF(ISBLANK(A15),"", IFERROR(IF(E15, F15, G15) * IF(ISBLANK(D15), C$1,D15) + C15, "")) -> 0.0403125 | E15: FALSE | G15: =IFERROR(VLOOKUP(A15, 'Price Sheet'!$A$2:$B1010, 2, false), "") -> 0.0215 | J15: =IF(ISBLANK(I15),"", IFERROR(IF(L15, M15, N15) * IF(ISBLANK(K15), K$1,K15), "")) | L15: FALSE | N15: =IFERROR(VLOOKUP(I15, 'Price Sheet'!$A$2:$B1010, 2, false), "")
A16: Yellow Powder | B16: =IF(ISBLANK(A16),"", IFERROR(IF(E16, F16, G16) * IF(ISBLANK(D16), C$1,D16) + C16, "")) -> 0.075 | E16: FALSE | G16: =IFERROR(VLOOKUP(A16, 'Price Sheet'!$A$2:$B1010, 2, false), "") -> 0.04 | J16: =IF(ISBLANK(I16),"", IFERROR(IF(L16, M16, N16) * IF(ISBLANK(K16), K$1,K16), "")) | L16: FALSE | N16: =IFERROR(VLOOKUP(I16, 'Price Sheet'!$A$2:$B1010, 2, false), "")
B17: =IF(ISBLANK(A17),"", IFERROR(IF(E17, F17, G17) * IF(ISBLANK(D17), C$1,D17) + C17, "")) | E17: FALSE | G17: =IFERROR(VLOOKUP(A17, 'Price Sheet'!$A$2:$B1010, 2, false), "") | J17: =IF(ISBLANK(I17),"", IFERROR(IF(L17, M17, N17) * IF(ISBLANK(K17), K$1,K17), "")) | L17: FALSE | N17: =IFERROR(VLOOKUP(I17, 'Price Sheet'!$A$2:$B1010, 2, false), "")
B18: =IF(ISBLANK(A18),"", IFERROR(IF(E18, F18, G18) * IF(ISBLANK(D18), C$1,D18) + C18, "")) | E18: FALSE | G18: =IFERROR(VLOOKUP(A18, 'Price Sheet'!$A$2:$B1010, 2, false), "") | J18: =IF(ISBLANK(I18),"", IFERROR(IF(L18, M18, N18) * IF(ISBLANK(K18), K$1,K18), "")) | L18: FALSE | N18: =IFERROR(VLOOKUP(I18, 'Price Sheet'!$A$2:$B1010, 2, false), "")
A19: Flaxseed Oil | B19: =IF(ISBLANK(A19),"", IFERROR(IF(E19, F19, G19) * IF(ISBLANK(D19), C$1,D19) + C19, "")) -> 2.2546875 | E19: FALSE | G19: =IFERROR(VLOOKUP(A19, 'Price Sheet'!$A$2:$B1010, 2, false), "") -> 1.2025 | J19: =IF(ISBLANK(I19),"", IFERROR(IF(L19, M19, N19) * IF(ISBLANK(K19), K$1,K19), "")) | L19: FALSE | N19: =IFERROR(VLOOKUP(I19, 'Price Sheet'!$A$2:$B1010, 2, false), "")
A20: Oil | B20: =IF(ISBLANK(A20),"", IFERROR(IF(E20, F20, G20) * IF(ISBLANK(D20), C$1,D20) + C20, "")) -> 0.992 | D20: 1.6 | E20: FALSE | G20: =IFERROR(VLOOKUP(A20, 'Price Sheet'!$A$2:$B1010, 2, false), "") -> 0.62 | J20: =IF(ISBLANK(I20),"", IFERROR(IF(L20, M20, N20) * IF(ISBLANK(K20), K$1,K20), "")) | L20: FALSE | N20: =IFERROR(VLOOKUP(I20, 'Price Sheet'!$A$2:$B1010, 2, false), "")
A21: Flour | B21: =IF(ISBLANK(A21),"", IFERROR(IF(E21, F21, G21) * IF(ISBLANK(D21), C$1,D21) + C21, "")) -> 0.8953125 | E21: FALSE | G21: =IFERROR(VLOOKUP(A21, 'Price Sheet'!$A$2:$B1010, 2, false), "") -> 0.4775 | J21: =IF(ISBLANK(I21),"", IFERROR(IF(L21, M21, N21) * IF(ISBLANK(K21), K$1,K21), "")) | L21: FALSE | N21: =IFERROR(VLOOKUP(I21, 'Price Sheet'!$A$2:$B1010, 2, false), "")
A22: Rice Flour | B22: =IF(ISBLANK(A22),"", IFERROR(IF(E22, F22, G22) * IF(ISBLANK(D22), C$1,D22) + C22, "")) -> 0.3609375 | E22: FALSE | G22: =IFERROR(VLOOKUP(A22, 'Price Sheet'!$A$2:$B1010, 2, false), "") -> 0.1925 | L22: FALSE
A23: Cornmeal | B23: =IF(ISBLANK(A23),"", IFERROR(IF(E23, F23, G23) * IF(ISBLANK(D23), C$1,D23) + C23, "")) -> 1.7203125 | E23: FALSE | G23: =IFERROR(VLOOKUP(A23, 'Price Sheet'!$A$2:$B1010, 2, false), "") -> 0.9175 | L23: FALSE
A24: Sugar | B24: =IF(ISBLANK(A24),"", IFERROR(IF(E24, F24, G24) * IF(ISBLANK(D24), C$1,D24) + C24, "")) -> 1.1390625 | E24: FALSE | G24: =IFERROR(VLOOKUP(A24, 'Price Sheet'!$A$2:$B1010, 2, false), "") -> 0.6075 | L24: FALSE
A25: Simple Syrup | B25: =IF(ISBLANK(A25),"", IFERROR(IF(E25, F25, G25) * IF(ISBLANK(D25), C$1,D25) + C25, "")) -> 5.4808594 | E25: FALSE | G25: =IFERROR(VLOOKUP(A25, 'Price Sheet'!$A$2:$B1010, 2, false), "") -> 2.923125 | L25: FALSE
A26: Huckleberry Extract | B26: =IF(ISBLANK(A26),"", IFERROR(IF(E26, F26, G26) * IF(ISBLANK(D26), C$1,D26) + C26, "")) -> 2.7421875 | E26: FALSE | G26: =IFERROR(VLOOKUP(A26, 'Price Sheet'!$A$2:$B1010, 2, false), "") -> 1.4625 | L26: TRUE
A27: Yeast | B27: =IF(ISBLANK(A27),"", IFERROR(IF(E27, F27, G27) * IF(ISBLANK(D27), C$1,D27) + C27, "")) -> 1.1524219 | E27: FALSE | G27: =IFERROR(VLOOKUP(A27, 'Price Sheet'!$A$2:$B1010, 2, false), "") -> 0.614625 | L27: FALSE
A28: Sun Cheese | B28: =IF(ISBLANK(A28),"", IFERROR(IF(E28, F28, G28) * IF(ISBLANK(D28), C$1,D28) + C28, "")) -> 4.4069883 | E28: FALSE | G28: =IFERROR(VLOOKUP(A28, 'Price Sheet'!$A$2:$B1010, 2, false), "") -> 2.3503937 | L28: FALSE
A29: Camas Paste | B29: =IF(ISBLANK(A29),"", IFERROR(IF(E29, F29, G29) * IF(ISBLANK(D29), C$1,D29) + C29, "")) -> 1.8515625 | E29: FALSE | G29: =IFERROR(VLOOKUP(A29, 'Price Sheet'!$A$2:$B1010, 2, false), "") -> 0.9875 | L29: FALSE
B30: =IF(ISBLANK(A30),"", IFERROR(IF(E30, F30, G30) * IF(ISBLANK(D30), C$1,D30) + C30, "")) | E30: FALSE | G30: =IFERROR(VLOOKUP(A30, 'Price Sheet'!$A$2:$B1010, 2, false), "") | L30: FALSE
A31: Base Paint | B31: =IF(ISBLANK(A31),"", IFERROR(IF(E31, F31, G31) * IF(ISBLANK(D31), C$1,D31) + C31, "")) -> 0.36924375 | E31: FALSE | G31: =IFERROR(VLOOKUP(A31, 'Price Sheet'!$A$2:$B1010, 2, false), "") -> 0.19693 | L31: FALSE
A32: Art Supplies | B32: =IF(ISBLANK(A32),"", IFERROR(IF(E32, F32, G32) * IF(ISBLANK(D32), C$1,D32) + C32, "")) -> 4.5195718 | E32: FALSE | G32: =IFERROR(VLOOKUP(A32, 'Price Sheet'!$A$2:$B1010, 2, false), "") -> 2.4104383 | J32: =IF(ISBLANK(I32),"", IFERROR(IF(L32, M32, N32) * IF(ISBLANK(K32), K$1,K32), "")) | L32: FALSE | N32: =IFERROR(VLOOKUP(I32, 'Price Sheet'!$A$2:$B1010, 2, false), "")
A33: Ink | B33: =IF(ISBLANK(A33),"", IFERROR(IF(E33, F33, G33) * IF(ISBLANK(D33), C$1,D33) + C33, "")) -> 2.5675313 | E33: FALSE | G33: =IFERROR(VLOOKUP(A33, 'Price Sheet'!$A$2:$B1010, 2, false), "") -> 1.36935 | J33: =IF(ISBLANK(I33),"", IFERROR(IF(L33, M33, N33) * IF(ISBLANK(K33), K$1,K33), "")) | L33: FALSE | N33: =IFERROR(VLOOKUP(I33, 'Price Sheet'!$A$2:$B1010, 2, false), "")
A34: Decorative Book | B34: =IF(ISBLANK(A34),"", IFERROR(IF(E34, F34, G34) * IF(ISBLANK(D34), C$1,D34) + C34, "")) -> 69.611784 | E34: FALSE | G34: =IFERROR(VLOOKUP(A34, 'Price Sheet'!$A$2:$B1010, 2, false), "") -> 37.126285 | J34: =IF(ISBLANK(I34),"", IFERROR(IF(L34, M34, N34) * IF(ISBLANK(K34), K$1,K34), "")) | L34: FALSE | N34: =IFERROR(VLOOKUP(I34, 'Price Sheet'!$A$2:$B1010, 2, false), "")
B35: =IF(ISBLANK(A35),"", IFERROR(IF(E35, F35, G35) * IF(ISBLANK(D35), C$1,D35) + C35, "")) | E35: FALSE | G35: =IFERROR(VLOOKUP(A35, 'Price Sheet'!$A$2:$B1010, 2, false), "") | J35: =IF(ISBLANK(I35),"", IFERROR(IF(L35, M35, N35) * IF(ISBLANK(K35), K$1,K35), "")) | L35: FALSE | N35: =IFERROR(VLOOKUP(I35, 'Price Sheet'!$A$2:$B1010, 2, false), "")
B36: =IF(ISBLANK(A36),"", IFERROR(IF(E36, F36, G36) * IF(ISBLANK(D36), C$1,D36) + C36, "")) | E36: FALSE | G36: =IFERROR(VLOOKUP(A36, 'Price Sheet'!$A$2:$B1010, 2, false), "") | J36: =IF(ISBLANK(I36),"", IFERROR(IF(L36, M36, N36) * IF(ISBLANK(K36), K$1,K36), "")) | L36: FALSE | N36: =IFERROR(VLOOKUP(I36, 'Price Sheet'!$A$2:$B1010, 2, false), "")
B37: =IF(ISBLANK(A37),"", IFERROR(IF(E37, F37, G37) * IF(ISBLANK(D37), C$1,D37) + C37, "")) | E37: FALSE | G37: =IFERROR(VLOOKUP(A37, 'Price Sheet'!$A$2:$B1010, 2, false), "") | J37: =IF(ISBLANK(I37),"", IFERROR(IF(L37, M37, N37) * IF(ISBLANK(K37), K$1,K37), "")) | L37: FALSE | N37: =IFERROR(VLOOKUP(I37, 'Price Sheet'!$A$2:$B1010, 2, false), "")
B38: =IF(ISBLANK(A38),"", IFERROR(IF(E38, F38, G38) * IF(ISBLANK(D38), C$1,D38) + C38, "")) | E38: FALSE | G38: =IFERROR(VLOOKUP(A38, 'Price Sheet'!$A$2:$B1010, 2, false), "") | J38: =IF(ISBLANK(I38),"", IFERROR(IF(L38, M38, N38) * IF(ISBLANK(K38), K$1,K38), "")) | L38: FALSE | N38: =IFERROR(VLOOKUP(I38, 'Price Sheet'!$A$2:$B1010, 2, false), "")
B39: =IF(ISBLANK(A39),"", IFERROR(IF(E39, F39, G39) * IF(ISBLANK(D39), C$1,D39) + C39, "")) | E39: FALSE | G39: =IFERROR(VLOOKUP(A39, 'Price Sheet'!$A$2:$B1010, 2, false), "") | J39: =IF(ISBLANK(I39),"", IFERROR(IF(L39, M39, N39) * IF(ISBLANK(K39), K$1,K39), "")) | L39: FALSE | N39: =IFERROR(VLOOKUP(I39, 'Price Sheet'!$A$2:$B1010, 2, false), "")
B40: =IF(ISBLANK(A40),"", IFERROR(IF(E40, F40, G40) * IF(ISBLANK(D40), C$1,D40) + C40, "")) | E40: FALSE | G40: =IFERROR(VLOOKUP(A40, 'Price Sheet'!$A$2:$B1010, 2, false), "") | J40: =IF(ISBLANK(I40),"", IFERROR(IF(L40, M40, N40) * IF(ISBLANK(K40), K$1,K40), "")) | L40: FALSE | N40: =IFERROR(VLOOKUP(I40, 'Price Sheet'!$A$2:$B1010, 2, false), "")
...

Sheet Recipes
L1: Product 1 | P1: Input 1 | V1: Input 2 | AB1: Input 3 | AH1: Input 4 | AN1: Input 5 | AT1: Input 6 | AZ1: Input 7 | BF1: Input 8 | BL1: Input 9
A2: Recipe Name | B2: Recipe Cost | C2: Skill | D2: Crafting Table | E2: Upgrade Used | F2: Input Multiplier | G2: Labor | H2: Cost from Calories | I2: Time | J2: Cost from time | K2: Active? | L2: Product | M2: Amount | N2: Cost Per | O2: unused | P2: Input Name | Q2: Input Amount | R2: Input Static | S2: Input Final Amount | T2: Input Per Ea. Cost | U2: Input Total Cost | V2: Input Name | W2: Input Amount | X2: Input Static | Y2: Input Final Amount | Z2: Input Per Ea. Cost | AA2: Input Total Cost | AB2: Input Name | AC2: Input Amount | AD2: Input Static | AE2: Input Final Amount | AF2: Input Per Ea. Cost | AG2: Input Total Cost | AH2: Input Name | AI2: Input Amount | AJ2: Input Static | AK2: Input Final Amount | AL2: Input Per Ea. Cost | AM2: Input Total Cost | AN2: Input Name | AO2: Input Amount | AP2: Input Static | AQ2: Input Final Amount | AR2: Input Per Ea. Cost | AS2: Input Total Cost | AT2: Input Name | AU2: Input Amount | AV2: Input Static | AW2: Input Final Amount | AX2: Input Per Ea. Cost | AY2: Input Total Cost | AZ2: Input Name | BA2: Input Amount | BB2: Input Static | BC2: Input Final Amount | BD2: Input Per Ea. Cost | BE2: Input Total Cost | BF2: Input Name | BG2: Input Amount | BH2: Input Static | BI2: Input Final Amount | BJ2: Input Per Ea. Cost | BK2: Input Total Cost | BL2: Input Name | BM2: Input Amount | BN2: Input Static | BO2: Input Final Amount | BP2: Input Per Ea. Cost | BQ2: Input Total Cost
A3: Dowel | B3: =H3+U3+AA3+AG3+AM3+AS3+AY3+BE3+BK3+J3+BQ3 -> 2.15 | C3: Logging | D3: Carpentry Table | E3: =IF(ISBLANK(D3), "", VLOOKUP(D3,'Crafting Tables'!$A$2:$B1015, 2, false)) -> Basic | F3: =IFERROR(IF(E3 = "None", 1, VLOOKUP(C3,General!$A$5:$L$35, SWITCH(E3, "Basic", 8, "Advanced", 10, "Modern", 12), false)),"") -> 0.55 | G3: 40 | H3: =IFERROR(VLOOKUP(C3, General!$A$5:$L$35, 6, false) * G3 / 1000, 0) -> 1.6 | I3: =0.4*60 -> 24 | J3: =IFERROR(I3*VLOOKUP(D3,'Crafting Tables'!$1:$1000, 4, false)*F3,"") -> 0 | K3: TRUE | L3: Dowel | M3: 16 | N3: =IF(ISBLANK(M3), "", $B3 / M3) -> 0.134375 | P3: Wood (Tag) | Q3: 2 | R3: FALSE | S3: =IF(ISBLANK(Q3), "", IF(R3, Q3, Q3*$F3 ) ) -> 1.1 | T3: =IF(ISBLANK(P3), 0, VLOOKUP(P3, 'Price Sheet'!$A$2:$B1015, 2, false)) -> 0.5 | U3: =IF(OR(ISBLANK(Q3), ISBLANK(T3)), "", T3*S3) -> 0.55 | X3: FALSE | Y3: =IF(ISBLANK(W3), "", IF(X3, W3, W3*$F3 ) ) | Z3: =IF(ISBLANK(V3), 0, VLOOKUP(V3, 'Price Sheet'!$A$2:$B1015, 2, false)) -> 0 | AA3: =IF(OR(ISBLANK(W3), ISBLANK(Z3)), "", Z3*Y3) | AD3: FALSE | AE3: =IF(ISBLANK(AC3), "", IF(AD3, AC3, AC3*$F3 ) ) | AF3: =IF(ISBLANK(AB3), 0, VLOOKUP(AB3, 'Price Sheet'!$A$2:$B1015, 2, false)) -> 0 | AG3: =IF(OR(ISBLANK(AC3), ISBLANK(AF3)), "", AF3*AE3) | AJ3: FALSE | AK3: =IF(ISBLANK(AI3), "", IF(AJ3, AI3, AI3*$F3 ) ) | AL3: =IF(ISBLANK(AH3), 0, VLOOKUP(AH3, 'Price Sheet'!$A$2:$B1015, 2, false)) -> 0 | AM3: =IF(OR(ISBLANK(AI3), ISBLANK(AL3)), "", AL3*AK3) | AP3: FALSE | AQ3: =IF(ISBLANK(AO3), "", IF(AP3, AO3, AO3*$F3 ) ) | AR3: =IF(ISBLANK(AN3), 0, VLOOKUP(AN3, 'Price Sheet'!$A$2:$B1015, 2, false)) -> 0 | AS3: =IF(OR(ISBLANK(AO3), ISBLANK(AR3)), "", AR3*AQ3) | AV3: FALSE | AW3: =IF(ISBLANK(AU3), "", IF(AV3, AU3, AU3*$F3 ) ) | AX3: =IF(ISBLANK(AT3), 0, VLOOKUP(AT3, 'Price Sheet'!$A$2:$B1015, 2, false)) -> 0 | AY3: =IF(OR(ISBLANK(AU3), ISBLANK(AX3)), "", AX3*AW3) | BB3: FALSE | BC3: =IF(ISBLANK(BA3), "", IF(BB3, BA3, BA3*$F3 ) ) | BD3: =IF(ISBLANK(AZ3), 0, VLOOKUP(AZ3, 'Price Sheet'!$A$2:$B1015, 2, false)) -> 0 | BE3: =IF(OR(ISBLANK(BA3), ISBLANK(BD3)), "", BD3*BC3) | BH3: FALSE | BI3: =IF(ISBLANK(BG3), "", IF(BH3, BG3, BG3*$F3 ) ) | BJ3: =IF(ISBLANK(BF3), 0, VLOOKUP(BF3, 'Price Sheet'!$A$2:$B1015, 2, false)) -> 0 | BK3: =IF(OR(ISBLANK(BG3), ISBLANK(BJ3)), "", BJ3*BI3) | BN3: FALSE | BO3: =IF(ISBLANK(BM3), "", IF(BN3, BM3, BM3*$F3 ) ) | BP3: =IF(ISBLANK(BL3), 0, VLOOKUP(BL3, 'Price Sheet'!$A$2:$B1015, 2, false)) -> 0 | BQ3: =IF(OR(ISBLANK(BM3), ISBLANK(BP3)), "", BP3*BO3)
A4: Hewn Log | B4: =H4+U4+AA4+AG4+AM4+AS4+AY4+BE4+BK4+J4+BQ4 -> 1.4978125 | C4: Logging | D4: Carpentry Table | E4: =IF(ISBLANK(D4), "", VLOOKUP(D4,'Crafting Tables'!$A$2:$B1015, 2, false)) -> Basic | F4: =IFERROR(IF(E4 = "None", 1, VLOOKUP(C4,General!$A$5:$L$35, SWITCH(E4, "Basic", 8, "Advanced", 10, "Modern", 12), false)),"") -> 0.55 | G4: 20 | H4: =IFERROR(VLOOKUP(C4, General!$A$5:$L$35, 6, false) * G4 / 1000, 0) -> 0.8 | J4: =IFERROR(I4*VLOOKUP(D4,'Crafting Tables'!$1:$1000, 4, false)*F4,"") -> 0 | K4: TRUE | L4: Hewn Log | M4: 1 | N4: =IF(ISBLANK(M4), "", $B4 / M4) -> 1.4978125 | P4: Wood (Tag) | Q4: 2 | R4: FALSE | S4: =IF(ISBLANK(Q4), "", IF(R4, Q4, Q4*$F4 ) ) -> 1.1 | T4: =IF(ISBLANK(P4), 0, VLOOKUP(P4, 'Price Sheet'!$A$2:$B1015, 2, false)) -> 0.5 | U4: =IF(OR(ISBLANK(Q4), ISBLANK(T4)), "", T4*S4) -> 0.55 | V4: Dowel | W4: 2 | X4: FALSE | Y4: =IF(ISBLANK(W4), "", IF(X4, W4, W4*$F4 ) ) -> 1.1 | Z4: =IF(ISBLANK(V4), 0, VLOOKUP(V4, 'Price Sheet'!$A$2:$B1015, 2, false)) -> 0.134375 | AA4: =IF(OR(ISBLANK(W4), ISBLANK(Z4)), "", Z4*Y4) -> 0.1478125 | AD4: FALSE | AE4: =IF(ISBLANK(AC4), "", IF(AD4, AC4, AC4*$F4 ) ) | AF4: =IF(ISBLANK(AB4), 0, VLOOKUP(AB4, 'Price Sheet'!$A$2:$B1015, 2, false)) -> 0 | AG4: =IF(OR(ISBLANK(AC4), ISBLANK(AF4)), "", AF4*AE4) | AJ4: FALSE | AK4: =IF(ISBLANK(AI4), "", IF(AJ4, AI4, AI4*$F4 ) ) | AL4: =IF(ISBLANK(AH4), 0, VLOOKUP(AH4, 'Price Sheet'!$A$2:$B1015, 2, false)) -> 0 | AM4: =IF(OR(ISBLANK(AI4), ISBLANK(AL4)), "", AL4*AK4) | AP4: FALSE | AQ4: =IF(ISBLANK(AO4), "", IF(AP4, AO4, AO4*$F4 ) ) | AR4: =IF(ISBLANK(AN4), 0, VLOOKUP(AN4, 'Price Sheet'!$A$2:$B1015, 2, false)) -> 0 | AS4: =IF(OR(ISBLANK(AO4), ISBLANK(AR4)), "", AR4*AQ4) | AV4: FALSE | AW4: =IF(ISBLANK(AU4), "", IF(AV4, AU4, AU4*$F4 ) ) | AX4: =IF(ISBLANK(AT4), 0, VLOOKUP(AT4, 'Price Sheet'!$A$2:$B1015, 2, false)) -> 0 | AY4: =IF(OR(ISBLANK(AU4), ISBLANK(AX4)), "", AX4*AW4) | BB4: FALSE | BC4: =IF(ISBLANK(BA4), "", IF(BB4, BA4, BA4*$F4 ) ) | BD4: =IF(ISBLANK(AZ4), 0, VLOOKUP(AZ4, 'Price Sheet'!$A$2:$B1015, 2, false)) -> 0 | BE4: =IF(OR(ISBLANK(BA4), ISBLANK(BD4)), "", BD4*BC4) | BH4: FALSE | BI4: =IF(ISBLANK(BG4), "", IF(BH4, BG4, BG4*$F4 ) ) | BJ4: =IF(ISBLANK(BF4), 0, VLOOKUP(BF4, 'Price Sheet'!$A$2:$B1015, 2, false)) -> 0 | BK4: =IF(OR(ISBLANK(BG4), ISBLANK(BJ4)), "", BJ4*BI4) | BN4: FALSE | BO4: =IF(ISBLANK(BM4), "", IF(BN4, BM4, BM4*$F4 ) ) | BP4: =IF(ISBLANK(BL4), 0, VLOOKUP(BL4, 'Price Sheet'!$A$2:$B1015, 2, false)) -> 0 | BQ4: =IF(OR(ISBLANK(BM4), ISBLANK(BP4)), "", BP4*BO4)
A5: Hewn (Workbench) | B5: =H5+U5+AA5+AG5+AM5+AS5+AY5+BE5+BK5+J5+BQ5 -> 1.8 | C5: None | D5: Workbench | E5: =IF(ISBLANK(D5), "", VLOOKUP(D5,'Crafting Tables'!$A$2:$B1015, 2, false)) -> None | F5: =IFERROR(IF(E5 = "None", 1, VLOOKUP(C5,General!$A$5:$L$35, SWITCH(E5, "Basic", 8, "Advanced", 10, "Modern", 12), false)),"") -> 1 | G5: 20 | H5: =IFERROR(VLOOKUP(C5, General!$A$5:$L$35, 6, false) * G5 / 1000, 0) -> 0.8 | J5: =IFERROR(I5*VLOOKUP(D5,'Crafting Tables'!$1:$1000, 4, false)*F5,"") -> 0 | K5: TRUE | L5: Hewn Log | M5: 1 | N5: =IF(ISBLANK(M5), "", $B5 / M5) -> 1.8 | P5: Wood (Tag) | Q5: 2 | R5: TRUE | S5: =IF(ISBLANK(Q5), "", IF(R5, Q5, Q5*$F5 ) ) -> 2 | T5: =IF(ISBLANK(P5), 0, VLOOKUP(P5, 'Price Sheet'!$A$2:$B1015, 2, false)) -> 0.5 | U5: =IF(OR(ISBLANK(Q5), ISBLANK(T5)), "", T5*S5) -> 1 | X5: FALSE | Y5: =IF(ISBLANK(W5), "", IF(X5, W5, W5*$F5 ) ) | Z5: =IF(ISBLANK(V5), 0, VLOOKUP(V5, 'Price Sheet'!$A$2:$B1015, 2, false)) -> 0 | AA5: =IF(OR(ISBLANK(W5), ISBLANK(Z5)), "", Z5*Y5) | AD5: FALSE | AE5: =IF(ISBLANK(AC5), "", IF(AD5, AC5, AC5*$F5 ) ) | AF5: =IF(ISBLANK(AB5), 0, VLOOKUP(AB5, 'Price Sheet'!$A$2:$B1015, 2, false)) -> 0 | AG5: =IF(OR(ISBLANK(AC5), ISBLANK(AF5)), "", AF5*AE5) | AJ5: FALSE | AK5: =IF(ISBLANK(AI5), "", IF(AJ5, AI5, AI5*$F5 ) ) | AL5: =IF(ISBLANK(AH5), 0, VLOOKUP(AH5, 'Price Sheet'!$A$2:$B1015, 2, false)) -> 0 | AM5: =IF(OR(ISBLANK(AI5), ISBLANK(AL5)), "", AL5*AK5) | AP5: FALSE | AQ5: =IF(ISBLANK(AO5), "", IF(AP5, AO5, AO5*$F5 ) ) | AR5: =IF(ISBLANK(AN5), 0, VLOOKUP(AN5, 'Price Sheet'!$A$2:$B1015, 2, false)) -> 0 | AS5: =IF(OR(ISBLANK(AO5), ISBLANK(AR5)), "", AR5*AQ5) | AV5: FALSE | AW5: =IF(ISBLANK(AU5), "", IF(AV5, AU5, AU5*$F5 ) ) | AX5: =IF(ISBLANK(AT5), 0, VLOOKUP(AT5, 'Price Sheet'!$A$2:$B1015, 2, false)) -> 0 | AY5: =IF(OR(ISBLANK(AU5), ISBLANK(AX5)), "", AX5*AW5) | BB5: FALSE | BC5: =IF(ISBLANK(BA5), "", IF(BB5, BA5, BA5*$F5 ) ) | BD5: =IF(ISBLANK(AZ5), 0, VLOOKUP(AZ5, 'Price Sheet'!$A$2:$B1015, 2, false)) -> 0 | BE5: =IF(OR(ISBLANK(BA5), ISBLANK(BD5)), "", BD5*BC5) | BH5: FALSE | BI5: =IF(ISBLANK(BG5), "", IF(BH5, BG5, BG5*$F5 ) ) | BJ5: =IF(ISBLANK(BF5), 0, VLOOKUP(BF5, 'Price Sheet'!$A$2:$B1015, 2, false)) -> 0 | BK5: =IF(OR(ISBLANK(BG5), ISBLANK(BJ5)), "", BJ5*BI5) | BN5: FALSE | BO5: =IF(ISBLANK(BM5), "", IF(BN5, BM5, BM5*$F5 ) ) | BP5: =IF(ISBLANK(BL5), 0, VLOOKUP(BL5, 'Price Sheet'!$A$2:$B1015, 2, false)) -> 0 | BQ5: =IF(OR(ISBLANK(BM5), ISBLANK(BP5)), "", BP5*BO5)
A6: Board (Workbench) | B6: =H6+U6+AA6+AG6+AM6+AS6+AY6+BE6+BK6+J6+BQ6 -> 2.6 | C6: None | D6: Workbench | E6: =IF(ISBLANK(D6), "", VLOOKUP(D6,'Crafting Tables'!$A$2:$B1015, 2, false)) -> None | F6: =IFERROR(IF(E6 = "None", 1, VLOOKUP(C6,General!$A$5:$L$35, SWITCH(E6, "Basic", 8, "Advanced", 10, "Modern", 12), false)),"") -> 1 | G6: 40 | H6: =IFERROR(VLOOKUP(C6, General!$A$5:$L$35, 6, false) * G6 / 1000, 0) -> 1.6 | J6: =IFERROR(I6*VLOOKUP(D6,'Crafting Tables'!$1:$1000, 4, false)*F6,"") -> 0 | K6: TRUE | L6: Board | M6: 1 | N6: =IF(ISBLANK(M6), "", $B6 / M6) -> 2.6 | P6: Wood (Tag) | Q6: 2 | R6: TRUE | S6: =IF(ISBLANK(Q6), "", IF(R6, Q6, Q6*$F6 ) ) -> 2 | T6: =IF(ISBLANK(P6), 0, VLOOKUP(P6, 'Price Sheet'!$A$2:$B1015, 2, false)) -> 0.5 | U6: =IF(OR(ISBLANK(Q6), ISBLANK(T6)), "", T6*S6) -> 1 | X6: FALSE | Y6: =IF(ISBLANK(W6), "", IF(X6, W6, W6*$F6 ) ) | Z6: =IF(ISBLANK(V6), 0, VLOOKUP(V6, 'Price Sheet'!$A$2:$B1015, 2, false)) -> 0 | AA6: =IF(OR(ISBLANK(W6), ISBLANK(Z6)), "", Z6*Y6) | AD6: FALSE | AE6: =IF(ISBLANK(AC6), "", IF(AD6, AC6, AC6*$F6 ) ) | AF6: =IF(ISBLANK(AB6), 0, VLOOKUP(AB6, 'Price Sheet'!$A$2:$B1015, 2, false)) -> 0 | AG6: =IF(OR(ISBLANK(AC6), ISBLANK(AF6)), "", AF6*AE6) | AJ6: FALSE | AK6: =IF(ISBLANK(AI6), "", IF(AJ6, AI6, AI6*$F6 ) ) | AL6: =IF(ISBLANK(AH6), 0, VLOOKUP(AH6, 'Price Sheet'!$A$2:$B1015, 2, false)) -> 0 | AM6: =IF(OR(ISBLANK(AI6), ISBLANK(AL6)), "", AL6*AK6) | AP6: FALSE | AQ6: =IF(ISBLANK(AO6), "", IF(AP6, AO6, AO6*$F6 ) ) | AR6: =IF(ISBLANK(AN6), 0, VLOOKUP(AN6, 'Price Sheet'!$A$2:$B1015, 2, false)) -> 0 | AS6: =IF(OR(ISBLANK(AO6), ISBLANK(AR6)), "", AR6*AQ6) | AV6: FALSE | AW6: =IF(ISBLANK(AU6), "", IF(AV6, AU6, AU6*$F6 ) ) | AX6: =IF(ISBLANK(AT6), 0, VLOOKUP(AT6, 'Price Sheet'!$A$2:$B1015, 2, false)) -> 0 | AY6: =IF(OR(ISBLANK(AU6), ISBLANK(AX6)), "", AX6*AW6) | BB6: FALSE | BC6: =IF(ISBLANK(BA6), "", IF(BB6, BA6, BA6*$F6 ) ) | BD6: =IF(ISBLANK(AZ6), 0, VLOOKUP(AZ6, 'Price Sheet'!$A$2:$B1015, 2, false)) -> 0 | BE6: =IF(OR(ISBLANK(BA6), ISBLANK(BD6)), "", BD6*BC6) | BH6: FALSE | BI6: =IF(ISBLANK(BG6), "", IF(BH6, BG6, BG6*$F6 ) ) | BJ6: =IF(ISBLANK(BF6), 0, VLOOKUP(BF6, 'Price Sheet'!$A$2:$B1015, 2, false)) -> 0 | BK6: =IF(OR(ISBLANK(BG6), ISBLANK(BJ6)), "", BJ6*BI6) | BN6: FALSE | BO6: =IF(ISBLANK(BM6), "", IF(BN6, BM6, BM6*$F6 ) ) | BP6: =IF(ISBLANK(BL6), 0, VLOOKUP(BL6, 'Price Sheet'!$A$2:$B1015, 2, false)) -> 0 | BQ6: =IF(OR(ISBLANK(BM6), ISBLANK(BP6)), "", BP6*BO6)
A7: Board (Carpentry Table) | B7: =H7+U7+AA7+AG7+AM7+AS7+AY7+BE7+BK7+J7+BQ7 -> 1.275 | C7: Logging | D7: Carpentry Table | E7: =IF(ISBLANK(D7), "", VLOOKUP(D7,'Crafting Tables'!$A$2:$B1015, 2, false)) -> Basic | F7: =IFERROR(IF(E7 = "None", 1, VLOOKUP(C7,General!$A$5:$L$35, SWITCH(E7, "Basic", 8, "Advanced", 10, "Modern", 12), false)),"") -> 0.55 | G7: 25 | H7: =IFERROR(VLOOKUP(C7, General!$A$5:$L$35, 6, false) * G7 / 1000, 0) -> 1 | J7: =IFERROR(I7*VLOOKUP(D7,'Crafting Tables'!$1:$1000, 4, false)*F7,"") -> 0 | K7: TRUE | L7: Board | M7: 1 | N7: =IF(ISBLANK(M7), "", $B7 / M7) -> 1.275 | P7: Wood (Tag) | Q7: 1 | R7: FALSE | S7: =IF(ISBLANK(Q7), "", IF(R7, Q7, Q7*$F7 ) ) -> 0.55 | T7: =IF(ISBLANK(P7), 0, VLOOKUP(P7, 'Price Sheet'!$A$2:$B1015, 2, false)) -> 0.5 | U7: =IF(OR(ISBLANK(Q7), ISBLANK(T7)), "", T7*S7) -> 0.275 | X7: FALSE | Y7: =IF(ISBLANK(W7), "", IF(X7, W7, W7*$F7 ) ) | Z7: =IF(ISBLANK(V7), 0, VLOOKUP(V7, 'Price Sheet'!$A$2:$B1015, 2, false)) -> 0 | AA7: =IF(OR(ISBLANK(W7), ISBLANK(Z7)), "", Z7*Y7) | AD7: FALSE | AE7: =IF(ISBLANK(AC7), "", IF(AD7, AC7, AC7*$F7 ) ) | AF7: =IF(ISBLANK(AB7), 0, VLOOKUP(AB7, 'Price Sheet'!$A$2:$B1015, 2, false)) -> 0 | AG7: =IF(OR(ISBLANK(AC7), ISBLANK(AF7)), "", AF7*AE7) | AJ7: FALSE | AK7: =IF(ISBLANK(AI7), "", IF(AJ7, AI7, AI7*$F7 ) ) | AL7: =IF(ISBLANK(AH7), 0, VLOOKUP(AH7, 'Price Sheet'!$A$2:$B1015, 2, false)) -> 0 | AM7: =IF(OR(ISBLANK(AI7), ISBLANK(AL7)), "", AL7*AK7) | AP7: FALSE | AQ7: =IF(ISBLANK(AO7), "", IF(AP7, AO7, AO7*$F7 ) ) | AR7: =IF(ISBLANK(AN7), 0, VLOOKUP(AN7, 'Price Sheet'!$A$2:$B1015, 2, false)) -> 0 | AS7: =IF(OR(ISBLANK(AO7), ISBLANK(AR7)), "", AR7*AQ7) | AV7: FALSE | AW7: =IF(ISBLANK(AU7), "", IF(AV7, AU7, AU7*$F7 ) ) | AX7: =IF(ISBLANK(AT7), 0, VLOOKUP(AT7, 'Price Sheet'!$A$2:$B1015, 2, false)) -> 0 | AY7: =IF(OR(ISBLANK(AU7), ISBLANK(AX7)), "", AX7*AW7) | BB7: FALSE | BC7: =IF(ISBLANK(BA7), "", IF(BB7, BA7, BA7*$F7 ) ) | BD7: =IF(ISBLANK(AZ7), 0, VLOOKUP(AZ7, 'Price Sheet'!$A$2:$B1015, 2, false)) -> 0 | BE7: =IF(OR(ISBLANK(BA7), ISBLANK(BD7)), "", BD7*BC7) | BH7: FALSE | BI7: =IF(ISBLANK(BG7), "", IF(BH7, BG7, BG7*$F7 ) ) | BJ7: =IF(ISBLANK(BF7), 0, VLOOKUP(BF7, 'Price Sheet'!$A$2:$B1015, 2, false)) -> 0 | BK7: =IF(OR(ISBLANK(BG7), ISBLANK(BJ7)), "", BJ7*BI7) | BN7: FALSE | BO7: =IF(ISBLANK(BM7), "", IF(BN7, BM7, BM7*$F7 ) ) | BP7: =IF(ISBLANK(BL7), 0, VLOOKUP(BL7, 'Price Sheet'!$A$2:$B1015, 2, false)) -> 0 | BQ7: =IF(OR(ISBLANK(BM7), ISBLANK(BP7)), "", BP7*BO7)
A8: Particle Boards | B8: =H8+U8+AA8+AG8+AM8+AS8+AY8+BE8+BK8+J8+BQ8 -> 1.05 | C8: Logging | D8: Sawmill | E8: =IF(ISBLANK(D8), "", VLOOKUP(D8,'Crafting Tables'!$A$2:$B1015, 2, false)) -> Advanced | F8: =IFERROR(IF(E8 = "None", 1, VLOOKUP(C8,General!$A$5:$L$35, SWITCH(E8, "Basic", 8, "Advanced", 10, "Modern", 12), false)),"") -> 1 | G8: 20 | H8: =IFERROR(VLOOKUP(C8, General!$A$5:$L$35, 6, false) * G8 / 1000, 0) -> 0.8 | J8: =IFERROR(I8*VLOOKUP(D8,'Crafting Tables'!$1:$1000, 4, false)*F8,"") -> 0 | K8: FALSE | L8: Board | M8: 1 | N8: =IF(ISBLANK(M8), "", $B8 / M8) -> 1.05 | P8: Wood Pulp | Q8: 5 | R8: FALSE | S8: =IF(ISBLANK(Q8), "", IF(R8, Q8, Q8*$F8 ) ) -> 5 | T8: =IF(ISBLANK(P8), 0, VLOOKUP(P8, 'Price Sheet'!$A$2:$B1015, 2, false)) -> 0.05 | U8: =IF(OR(ISBLANK(Q8), ISBLANK(T8)), "", T8*S8) -> 0.25 | X8: FALSE | Y8: =IF(ISBLANK(W8), "", IF(X8, W8, W8*$F8 ) ) | Z8: =IF(ISBLANK(V8), 0, VLOOKUP(V8, 'Price Sheet'!$A$2:$B1015, 2, false)) -> 0 | AA8: =IF(OR(ISBLANK(W8), ISBLANK(Z8)), "", Z8*Y8) | AD8: FALSE | AE8: =IF(ISBLANK(AC8), "", IF(AD8, AC8, AC8*$F8 ) ) | AF8: =IF(ISBLANK(AB8), 0, VLOOKUP(AB8, 'Price Sheet'!$A$2:$B1015, 2, false)) -> 0 | AG8: =IF(OR(ISBLANK(AC8), ISBLANK(AF8)), "", AF8*AE8) | AJ8: FALSE | AK8: =IF(ISBLANK(AI8), "", IF(AJ8, AI8, AI8*$F8 ) ) | AL8: =IF(ISBLANK(AH8), 0, VLOOKUP(AH8, 'Price Sheet'!$A$2:$B1015, 2, false)) -> 0 | AM8: =IF(OR(ISBLANK(AI8), ISBLANK(AL8)), "", AL8*AK8) | AP8: FALSE | AQ8: =IF(ISBLANK(AO8), "", IF(AP8, AO8, AO8*$F8 ) ) | AR8: =IF(ISBLANK(AN8), 0, VLOOKUP(AN8, 'Price Sheet'!$A$2:$B1015, 2, false)) -> 0 | AS8: =IF(OR(ISBLANK(AO8), ISBLANK(AR8)), "", AR8*AQ8) | AV8: FALSE | AW8: =IF(ISBLANK(AU8), "", IF(AV8, AU8, AU8*$F8 ) ) | AX8: =IF(ISBLANK(AT8), 0, VLOOKUP(AT8, 'Price Sheet'!$A$2:$B1015, 2, false)) -> 0 | AY8: =IF(OR(ISBLANK(AU8), ISBLANK(AX8)), "", AX8*AW8) | BB8: FALSE | BC8: =IF(ISBLANK(BA8), "", IF(BB8, BA8, BA8*$F8 ) ) | BD8: =IF(ISBLANK(AZ8), 0, VLOOKUP(AZ8, 'Price Sheet'!$A$2:$B1015, 2, false)) -> 0 | BE8: =IF(OR(ISBLANK(BA8), ISBLANK(BD8)), "", BD8*BC8) | BH8: FALSE | BI8: =IF(ISBLANK(BG8), "", IF(BH8, BG8, BG8*$F8 ) ) | BJ8: =IF(ISBLANK(BF8), 0, VLOOKUP(BF8, 'Price Sheet'!$A$2:$B1015, 2, false)) -> 0 | BK8: =IF(OR(ISBLANK(BG8), ISBLANK(BJ8)), "", BJ8*BI8) | BN8: FALSE | BO8: =IF(ISBLANK(BM8), "", IF(BN8, BM8, BM8*$F8 ) ) | BP8: =IF(ISBLANK(BL8), 0, VLOOKUP(BL8, 'Price Sheet'!$A$2:$B1015, 2, false)) -> 0 | BQ8: =IF(OR(ISBLANK(BM8), ISBLANK(BP8)), "", BP8*BO8)
A9: Saw Boards | B9: =H9+U9+AA9+AG9+AM9+AS9+AY9+BE9+BK9+J9+BQ9 -> 1.8 | C9: Logging | D9: Sawmill | E9: =IF(ISBLANK(D9), "", VLOOKUP(D9,'Crafting Tables'!$A$2:$B1015, 2, false)) -> Advanced | F9: =IFERROR(IF(E9 = "None", 1, VLOOKUP(C9,General!$A$5:$L$35, SWITCH(E9, "Basic", 8, "Advanced", 10, "Modern", 12), false)),"") -> 1 | G9: 20 | H9: =IFERROR(VLOOKUP(C9, General!$A$5:$L$35, 6, false) * G9 / 1000, 0) -> 0.8 | J9: =IFERROR(I9*VLOOKUP(D9,'Crafting Tables'!$1:$1000, 4, false)*F9,"") -> 0 | K9: TRUE | L9: Board | M9: 3 | N9: =IF(ISBLANK(M9), "", $B9 / M9) -> 0.6 | P9: Wood (Tag) | Q9: 2 | R9: FALSE | S9: =IF(ISBLANK(Q9), "", IF(R9, Q9, Q9*$F9 ) ) -> 2 | T9: =IF(ISBLANK(P9), 0, VLOOKUP(P9, 'Price Sheet'!$A$2:$B1015, 2, false)) -> 0.5 | U9: =IF(OR(ISBLANK(Q9), ISBLANK(T9)), "", T9*S9) -> 1 | X9: FALSE | Y9: =IF(ISBLANK(W9), "", IF(X9, W9, W9*$F9 ) ) | Z9: =IF(ISBLANK(V9), 0, VLOOKUP(V9, 'Price Sheet'!$A$2:$B1015, 2, false)) -> 0 | AA9: =IF(OR(ISBLANK(W9), ISBLANK(Z9)), "", Z9*Y9) | AD9: FALSE | AE9: =IF(ISBLANK(AC9), "", IF(AD9, AC9, AC9*$F9 ) ) | AF9: =IF(ISBLANK(AB9), 0, VLOOKUP(AB9, 'Price Sheet'!$A$2:$B1015, 2, false)) -> 0 | AG9: =IF(OR(ISBLANK(AC9), ISBLANK(AF9)), "", AF9*AE9) | AJ9: FALSE | AK9: =IF(ISBLANK(AI9), "", IF(AJ9, AI9, AI9*$F9 ) ) | AL9: =IF(ISBLANK(AH9), 0, VLOOKUP(AH9, 'Price Sheet'!$A$2:$B1015, 2, false)) -> 0 | AM9: =IF(OR(ISBLANK(AI9), ISBLANK(AL9)), "", AL9*AK9) | AP9: FALSE | AQ9: =IF(ISBLANK(AO9), "", IF(AP9, AO9, AO9*$F9 ) ) | AR9: =IF(ISBLANK(AN9), 0, VLOOKUP(AN9, 'Price Sheet'!$A$2:$B1015, 2, false)) -> 0 | AS9: =IF(OR(ISBLANK(AO9), ISBLANK(AR9)), "", AR9*AQ9) | AV9: FALSE | AW9: =IF(ISBLANK(AU9), "", IF(AV9, AU9, AU9*$F9 ) ) | AX9: =IF(ISBLANK(AT9), 0, VLOOKUP(AT9, 'Price Sheet'!$A$2:$B1015, 2, false)) -> 0 | AY9: =IF(OR(ISBLANK(AU9), ISBLANK(AX9)), "", AX9*AW9) | BB9: FALSE | BC9: =IF(ISBLANK(BA9), "", IF(BB9, BA9, BA9*$F9 ) ) | BD9: =IF(ISBLANK(AZ9), 0, VLOOKUP(AZ9, 'Price Sheet'!$A$2:$B1015, 2, false)) -> 0 | BE9: =IF(OR(ISBLANK(BA9), ISBLANK(BD9)), "", BD9*BC9) | BH9: FALSE | BI9: =IF(ISBLANK(BG9), "", IF(BH9, BG9, BG9*$F9 ) ) | BJ9: =IF(ISBLANK(BF9), 0, VLOOKUP(BF9, 'Price Sheet'!$A$2:$B1015, 2, false)) -> 0 | BK9: =IF(OR(ISBLANK(BG9), ISBLANK(BJ9)), "", BJ9*BI9) | BN9: FALSE | BO9: =IF(ISBLANK(BM9), "", IF(BN9, BM9, BM9*$F9 ) ) | BP9: =IF(ISBLANK(BL9), 0, VLOOKUP(BL9, 'Price Sheet'!$A$2:$B1015, 2, false)) -> 0 | BQ9: =IF(OR(ISBLANK(BM9), ISBLANK(BP9)), "", BP9*BO9)
A10: Butchery Table | B10: =H10+U10+AA10+AG10+AM10+AS10+AY10+BE10+BK10+J10+BQ10 -> 21.35 | C10: Logging | D10: Carpentry Table | E10: =IF(ISBLANK(D10), "", VLOOKUP(D10,'Crafting Tables'!$A$2:$B1015, 2, false)) -> Basic | F10: =IFERROR(IF(E10 = "None", 1, VLOOKUP(C10,General!$A$5:$L$35, SWITCH(E10, "Basic", 8, "Advanced", 10, "Modern", 12), false)),"") -> 0.55 | G10: 300 | H10: =IFERROR(VLOOKUP(C10, General!$A$5:$L$35, 6, false) * G10 / 1000, 0) -> 12 | J10: =IFERROR(I10*VLOOKUP(D10,'Crafting Tables'!$1:$1000, 4, false)*F10,"") -> 0 | K10: TRUE | L10: Butchery Table | M10: 1 | N10: =IF(ISBLANK(M10), "", $B10 / M10) -> 21.35 | P10: Hewn Log | Q10: 10 | R10: FALSE | S10: =IF(ISBLANK(Q10), "", IF(R10, Q10, Q10*$F10 ) ) -> 5.5 | T10: =IF(ISBLANK(P10), 0, VLOOKUP(P10, 'Price Sheet'!$A$2:$B1015, 2, false)) -> 0.8 | U10: =IF(OR(ISBLANK(Q10), ISBLANK(T10)), "", T10*S10) -> 4.4 | V10: Board | W10: 20 | X10: FALSE | Y10: =IF(ISBLANK(W10), "", IF(X10, W10, W10*$F10 ) ) -> 11 | Z10: =IF(ISBLANK(V10), 0, VLOOKUP(V10, 'Price Sheet'!$A$2:$B1015, 2, false)) -> 0.45 | AA10: =IF(OR(ISBLANK(W10), ISBLANK(Z10)), "", Z10*Y10) -> 4.95 | AD10: FALSE | AE10: =IF(ISBLANK(AC10), "", IF(AD10, AC10, AC10*$F10 ) ) | AF10: =IF(ISBLANK(AB10), 0, VLOOKUP(AB10, 'Price Sheet'!$A$2:$B1015, 2, false)) -> 0 | AG10: =IF(OR(ISBLANK(AC10), ISBLANK(AF10)), "", AF10*AE10) | AJ10: FALSE | AK10: =IF(ISBLANK(AI10), "", IF(AJ10, AI10, AI10*$F10 ) ) | AL10: =IF(ISBLANK(AH10), 0, VLOOKUP(AH10, 'Price Sheet'!$A$2:$B1015, 2, false)) -> 0 | AM10: =IF(OR(ISBLANK(AI10), ISBLANK(AL10)), "", AL10*AK10) | AP10: FALSE | AQ10: =IF(ISBLANK(AO10), "", IF(AP10, AO10, AO10*$F10 ) ) | AR10: =IF(ISBLANK(AN10), 0, VLOOKUP(AN10, 'Price Sheet'!$A$2:$B1015, 2, false)) -> 0 | AS10: =IF(OR(ISBLANK(AO10), ISBLANK(AR10)), "", AR10*AQ10) | AV10: FALSE | AW10: =IF(ISBLANK(AU10), "", IF(AV10, AU10, AU10*$F10 ) ) | AX10: =IF(ISBLANK(AT10), 0, VLOOKUP(AT10, 'Price Sheet'!$A$2:$B1015, 2, false)) -> 0 | AY10: =IF(OR(ISBLANK(AU10), ISBLANK(AX10)), "", AX10*AW10) | BB10: FALSE | BC10: =IF(ISBLANK(BA10), "", IF(BB10, BA10, BA10*$F10 ) ) | BD10: =IF(ISBLANK(AZ10), 0, VLOOKUP(AZ10, 'Price Sheet'!$A$2:$B1015, 2, false)) -> 0 | BE10: =IF(OR(ISBLANK(BA10), ISBLANK(BD10)), "", BD10*BC10) | BH10: FALSE | BI10: =IF(ISBLANK(BG10), "", IF(BH10, BG10, BG10*$F10 ) ) | BJ10: =IF(ISBLANK(BF10), 0, VLOOKUP(BF10, 'Price Sheet'!$A$2:$B1015, 2, false)) -> 0 | BK10: =IF(OR(ISBLANK(BG10), ISBLANK(BJ10)), "", BJ10*BI10) | BN10: FALSE | BO10: =IF(ISBLANK(BM10), "", IF(BN10, BM10, BM10*$F10 ) ) | BP10: =IF(ISBLANK(BL10), 0, VLOOKUP(BL10, 'Price Sheet'!$A$2:$B1015, 2, false)) -> 0 | BQ10: =IF(OR(ISBLANK(BM10), ISBLANK(BP10)), "", BP10*BO10)
A11: Fiber Scutching Station | B11: =H11+U11+AA11+AG11+AM11+AS11+AY11+BE11+BK11+J11+BQ11 -> 21.35 | C11: Logging | D11: Carpentry Table | E11: =IF(ISBLANK(D11), "", VLOOKUP(D11,'Crafting Tables'!$A$2:$B1015, 2, false)) -> Basic | F11: =IFERROR(IF(E11 = "None", 1, VLOOKUP(C11,General!$A$5:$L$35, SWITCH(E11, "Basic", 8, "Advanced", 10, "Modern", 12), false)),"") -> 0.55 | G11: 300 | H11: =IFERROR(VLOOKUP(C11, General!$A$5:$L$35, 6, false) * G11 / 1000, 0) -> 12 | J11: =IFERROR(I11*VLOOKUP(D11,'Crafting Tables'!$1:$1000, 4, false)*F11,"") -> 0 | K11: TRUE | L11: Fiber Scutching Station | M11: 1 | N11: =IF(ISBLANK(M11), "", $B11 / M11) -> 21.35 | P11: Hewn Log | Q11: 10 | R11: FALSE | S11: =IF(ISBLANK(Q11), "", IF(R11, Q11, Q11*$F11 ) ) -> 5.5 | T11: =IF(ISBLANK(P11), 0, VLOOKUP(P11, 'Price Sheet'!$A$2:$B1015, 2, false)) -> 0.8 | U11: =IF(OR(ISBLANK(Q11), ISBLANK(T11)), "", T11*S11) -> 4.4 | V11: Board | W11: 20 | X11: FALSE | Y11: =IF(ISBLANK(W11), "", IF(X11, W11, W11*$F11 ) ) -> 11 | Z11: =IF(ISBLANK(V11), 0, VLOOKUP(V11, 'Price Sheet'!$A$2:$B1015, 2, false)) -> 0.45 | AA11: =IF(OR(ISBLANK(W11), ISBLANK(Z11)), "", Z11*Y11) -> 4.95 | AD11: FALSE | AE11: =IF(ISBLANK(AC11), "", IF(AD11, AC11, AC11*$F11 ) ) | AF11: =IF(ISBLANK(AB11), 0, VLOOKUP(AB11, 'Price Sheet'!$A$2:$B1015, 2, false)) -> 0 | AG11: =IF(OR(ISBLANK(AC11), ISBLANK(AF11)), "", AF11*AE11) | AJ11: FALSE | AK11: =IF(ISBLANK(AI11), "", IF(AJ11, AI11, AI11*$F11 ) ) | AL11: =IF(ISBLANK(AH11), 0, VLOOKUP(AH11, 'Price Sheet'!$A$2:$B1015, 2, false)) -> 0 | AM11: =IF(OR(ISBLANK(AI11), ISBLANK(AL11)), "", AL11*AK11) | AP11: FALSE | AQ11: =IF(ISBLANK(AO11), "", IF(AP11, AO11, AO11*$F11 ) ) | AR11: =IF(ISBLANK(AN11), 0, VLOOKUP(AN11, 'Price Sheet'!$A$2:$B1015, 2, false)) -> 0 | AS11: =IF(OR(ISBLANK(AO11), ISBLANK(AR11)), "", AR11*AQ11) | AV11: FALSE | AW11: =IF(ISBLANK(AU11), "", IF(AV11, AU11, AU11*$F11 ) ) | AX11: =IF(ISBLANK(AT11), 0, VLOOKUP(AT11, 'Price Sheet'!$A$2:$B1015, 2, false)) -> 0 | AY11: =IF(OR(ISBLANK(AU11), ISBLANK(AX11)), "", AX11*AW11) | BB11: FALSE | BC11: =IF(ISBLANK(BA11), "", IF(BB11, BA11, BA11*$F11 ) ) | BD11: =IF(ISBLANK(AZ11), 0, VLOOKUP(AZ11, 'Price Sheet'!$A$2:$B1015, 2, false)) -> 0 | BE11: =IF(OR(ISBLANK(BA11), ISBLANK(BD11)), "", BD11*BC11) | BH11: FALSE | BI11: =IF(ISBLANK(BG11), "", IF(BH11, BG11, BG11*$F11 ) ) | BJ11: =IF(ISBLANK(BF11), 0, VLOOKUP(BF11, 'Price Sheet'!$A$2:$B1015, 2, false)) -> 0 | BK11: =IF(OR(ISBLANK(BG11), ISBLANK(BJ11)), "", BJ11*BI11) | BN11: FALSE | BO11: =IF(ISBLANK(BM11), "", IF(BN11, BM11, BM11*$F11 ) ) | BP11: =IF(ISBLANK(BL11), 0, VLOOKUP(BL11, 'Price Sheet'!$A$2:$B1015, 2, false)) -> 0 | BQ11: =IF(OR(ISBLANK(BM11), ISBLANK(BP11)), "", BP11*BO11)
A12: Hewn Bench | B12: =H12+U12+AA12+AG12+AM12+AS12+AY12+BE12+BK12+J12+BQ12 -> 11.805 | C12: Logging | D12: Carpentry Table | E12: =IF(ISBLANK(D12), "", VLOOKUP(D12,'Crafting Tables'!$A$2:$B1015, 2, false)) -> Basic | F12: =IFERROR(IF(E12 = "None", 1, VLOOKUP(C12,General!$A$5:$L$35, SWITCH(E12, "Basic", 8, "Advanced", 10, "Modern", 12), false)),"") -> 0.55 | G12: 60 | H12: =IFERROR(VLOOKUP(C12, General!$A$5:$L$35, 6, false) * G12 / 1000, 0) -> 2.4 | J12: =IFERROR(I12*VLOOKUP(D12,'Crafting Tables'!$1:$1000, 4, false)*F12,"") -> 0 | K12: TRUE | L12: Hewn Bench | M12: 1 | N12: =IF(ISBLANK(M12), "", $B12 / M12) -> 11.805 | P12: Hewn Log | Q12: 18 | R12: FALSE | S12: =IF(ISBLANK(Q12), "", IF(R12, Q12, Q12*$F12 ) ) -> 9.9 | T12: =IF(ISBLANK(P12), 0, VLOOKUP(P12, 'Price Sheet'!$A$2:$B1015, 2, false)) -> 0.8 | U12: =IF(OR(ISBLANK(Q12), ISBLANK(T12)), "", T12*S12) -> 7.92 | V12: Board | W12: 6 | X12: FALSE | Y12: =IF(ISBLANK(W12), "", IF(X12, W12, W12*$F12 ) ) -> 3.3 | Z12: =IF(ISBLANK(V12), 0, VLOOKUP(V12, 'Price Sheet'!$A$2:$B1015, 2, false)) -> 0.45 | AA12: =IF(OR(ISBLANK(W12), ISBLANK(Z12)), "", Z12*Y12) -> 1.485 | AD12: FALSE | AE12: =IF(ISBLANK(AC12), "", IF(AD12, AC12, AC12*$F12 ) ) | AF12: =IF(ISBLANK(AB12), 0, VLOOKUP(AB12, 'Price Sheet'!$A$2:$B1015, 2, false)) -> 0 | AG12: =IF(OR(ISBLANK(AC12), ISBLANK(AF12)), "", AF12*AE12) | AJ12: FALSE | AK12: =IF(ISBLANK(AI12), "", IF(AJ12, AI12, AI12*$F12 ) ) | AL12: =IF(ISBLANK(AH12), 0, VLOOKUP(AH12, 'Price Sheet'!$A$2:$B1015, 2, false)) -> 0 | AM12: =IF(OR(ISBLANK(AI12), ISBLANK(AL12)), "", AL12*AK12) | AP12: FALSE | AQ12: =IF(ISBLANK(AO12), "", IF(AP12, AO12, AO12*$F12 ) ) | AR12: =IF(ISBLANK(AN12), 0, VLOOKUP(AN12, 'Price Sheet'!$A$2:$B1015, 2, false)) -> 0 | AS12: =IF(OR(ISBLANK(AO12), ISBLANK(AR12)), "", AR12*AQ12) | AV12: FALSE | AW12: =IF(ISBLANK(AU12), "", IF(AV12, AU12, AU12*$F12 ) ) | AX12: =IF(ISBLANK(AT12), 0, VLOOKUP(AT12, 'Price Sheet'!$A$2:$B1015, 2, false)) -> 0 | AY12: =IF(OR(ISBLANK(AU12), ISBLANK(AX12)), "", AX12*AW12) | BB12: FALSE | BC12: =IF(ISBLANK(BA12), "", IF(BB12, BA12, BA12*$F12 ) ) | BD12: =IF(ISBLANK(AZ12), 0, VLOOKUP(AZ12, 'Price Sheet'!$A$2:$B1015, 2, false)) -> 0 | BE12: =IF(OR(ISBLANK(BA12), ISBLANK(BD12)), "", BD12*BC12) | BH12: FALSE | BI12: =IF(ISBLANK(BG12), "", IF(BH12, BG12, BG12*$F12 ) ) | BJ12: =IF(ISBLANK(BF12), 0, VLOOKUP(BF12, 'Price Sheet'!$A$2:$B1015, 2, false)) -> 0 | BK12: =IF(OR(ISBLANK(BG12), ISBLANK(BJ12)), "", BJ12*BI12) | BN12: FALSE | BO12: =IF(ISBLANK(BM12), "", IF(BN12, BM12, BM12*$F12 ) ) | BP12: =IF(ISBLANK(BL12), 0, VLOOKUP(BL12, 'Price Sheet'!$A$2:$B1015, 2, false)) -> 0 | BQ12: =IF(OR(ISBLANK(BM12), ISBLANK(BP12)), "", BP12*BO12)
A13: Hewn Chair | B13: =H13+U13+AA13+AG13+AM13+AS13+AY13+BE13+BK13+J13+BQ13 -> 10.65 | C13: Logging | D13: Carpentry Table | E13: =IF(ISBLANK(D13), "", VLOOKUP(D13,'Crafting Tables'!$A$2:$B1015, 2, false)) -> Basic | F13: =IFERROR(IF(E13 = "None", 1, VLOOKUP(C13,General!$A$5:$L$35, SWITCH(E13, "Basic", 8, "Advanced", 10, "Modern", 12), false)),"") -> 0.55 | G13: 60 | H13: =IFERROR(VLOOKUP(C13, General!$A$5:$L$35, 6, false) * G13 / 1000, 0) -> 2.4 | J13: =IFERROR(I13*VLOOKUP(D13,'Crafting Tables'!$1:$1000, 4, false)*F13,"") -> 0 | K13: TRUE | L13: Hewn Chair | M13: 1 | N13: =IF(ISBLANK(M13), "", $B13 / M13) -> 10.65 | P13: Hewn Log | Q13: 12 | R13: FALSE | S13: =IF(ISBLANK(Q13), "", IF(R13, Q13, Q13*$F13 ) ) -> 6.6 | T13: =IF(ISBLANK(P13), 0, VLOOKUP(P13, 'Price Sheet'!$A$2:$B1015, 2, false)) -> 0.8 | U13: =IF(OR(ISBLANK(Q13), ISBLANK(T13)), "", T13*S13) -> 5.28 | V13: Board | W13: 12 | X13: FALSE | Y13: =IF(ISBLANK(W13), "", IF(X13, W13, W13*$F13 ) ) -> 6.6 | Z13: =IF(ISBLANK(V13), 0, VLOOKUP(V13, 'Price Sheet'!$A$2:$B1015, 2, false)) -> 0.45 | AA13: =IF(OR(ISBLANK(W13), ISBLANK(Z13)), "", Z13*Y13) -> 2.97 | AD13: FALSE | AE13: =IF(ISBLANK(AC13), "", IF(AD13, AC13, AC13*$F13 ) ) | AF13: =IF(ISBLANK(AB13), 0, VLOOKUP(AB13, 'Price Sheet'!$A$2:$B1015, 2, false)) -> 0 | AG13: =IF(OR(ISBLANK(AC13), ISBLANK(AF13)), "", AF13*AE13) | AJ13: FALSE | AK13: =IF(ISBLANK(AI13), "", IF(AJ13, AI13, AI13*$F13 ) ) | AL13: =IF(ISBLANK(AH13), 0, VLOOKUP(AH13, 'Price Sheet'!$A$2:$B1015, 2, false)) -> 0 | AM13: =IF(OR(ISBLANK(AI13), ISBLANK(AL13)), "", AL13*AK13) | AP13: FALSE | AQ13: =IF(ISBLANK(AO13), "", IF(AP13, AO13, AO13*$F13 ) ) | AR13: =IF(ISBLANK(AN13), 0, VLOOKUP(AN13, 'Price Sheet'!$A$2:$B1015, 2, false)) -> 0 | AS13: =IF(OR(ISBLANK(AO13), ISBLANK(AR13)), "", AR13*AQ13) | AV13: FALSE | AW13: =IF(ISBLANK(AU13), "", IF(AV13, AU13, AU13*$F13 ) ) | AX13: =IF(ISBLANK(AT13), 0, VLOOKUP(AT13, 'Price Sheet'!$A$2:$B1015, 2, false)) -> 0 | AY13: =IF(OR(ISBLANK(AU13), ISBLANK(AX13)), "", AX13*AW13) | BB13: FALSE | BC13: =IF(ISBLANK(BA13), "", IF(BB13, BA13, BA13*$F13 ) ) | BD13: =IF(ISBLANK(AZ13), 0, VLOOKUP(AZ13, 'Price Sheet'!$A$2:$B1015, 2, false)) -> 0 | BE13: =IF(OR(ISBLANK(BA13), ISBLANK(BD13)), "", BD13*BC13) | BH13: FALSE | BI13: =IF(ISBLANK(BG13), "", IF(BH13, BG13, BG13*$F13 ) ) | BJ13: =IF(ISBLANK(BF13), 0, VLOOKUP(BF13, 'Price Sheet'!$A$2:$B1015, 2, false)) -> 0 | BK13: =IF(OR(ISBLANK(BG13), ISBLANK(BJ13)), "", BJ13*BI13) | BN13: FALSE | BO13: =IF(ISBLANK(BM13), "", IF(BN13, BM13, BM13*$F13 ) ) | BP13: =IF(ISBLANK(BL13), 0, VLOOKUP(BL13, 'Price Sheet'!$A$2:$B1015, 2, false)) -> 0 | BQ13: =IF(OR(ISBLANK(BM13), ISBLANK(BP13)), "", BP13*BO13)
A14: Hewn Door | B14: =H14+U14+AA14+AG14+AM14+AS14+AY14+BE14+BK14+J14+BQ14 -> 3.28 | C14: Logging | D14: Carpentry Table | E14: =IF(ISBLANK(D14), "", VLOOKUP(D14,'Crafting Tables'!$A$2:$B1015, 2, false)) -> Basic | F14: =IFERROR(IF(E14 = "None", 1, VLOOKUP(C14,General!$A$5:$L$35, SWITCH(E14, "Basic", 8, "Advanced", 10, "Modern", 12), false)),"") -> 0.55 | G14: 60 | H14: =IFERROR(VLOOKUP(C14, General!$A$5:$L$35, 6, false) * G14 / 1000, 0) -> 2.4 | J14: =IFERROR(I14*VLOOKUP(D14,'Crafting Tables'!$1:$1000, 4, false)*F14,"") -> 0 | K14: TRUE | L14: Hewn Door | M14: 1 | N14: =IF(ISBLANK(M14), "", $B14 / M14) -> 3.28 | P14: Hewn Log | Q14: 2 | R14: FALSE | S14: =IF(ISBLANK(Q14), "", IF(R14, Q14, Q14*$F14 ) ) -> 1.1 | T14: =IF(ISBLANK(P14), 0, VLOOKUP(P14, 'Price Sheet'!$A$2:$B1015, 2, false)) -> 0.8 | U14: =IF(OR(ISBLANK(Q14), ISBLANK(T14)), "", T14*S14) -> 0.88 | X14: FALSE | Y14: =IF(ISBLANK(W14), "", IF(X14, W14, W14*$F14 ) ) | Z14: =IF(ISBLANK(V14), 0, VLOOKUP(V14, 'Price Sheet'!$A$2:$B1015, 2, false)) -> 0 | AA14: =IF(OR(ISBLANK(W14), ISBLANK(Z14)), "", Z14*Y14) | AD14: FALSE | AE14: =IF(ISBLANK(AC14), "", IF(AD14, AC14, AC14*$F14 ) ) | AF14: =IF(ISBLANK(AB14), 0, VLOOKUP(AB14, 'Price Sheet'!$A$2:$B1015, 2, false)) -> 0 | AG14: =IF(OR(ISBLANK(AC14), ISBLANK(AF14)), "", AF14*AE14) | AJ14: FALSE | AK14: =IF(ISBLANK(AI14), "", IF(AJ14, AI14, AI14*$F14 ) ) | AL14: =IF(ISBLANK(AH14), 0, VLOOKUP(AH14, 'Price Sheet'!$A$2:$B1015, 2, false)) -> 0 | AM14: =IF(OR(ISBLANK(AI14), ISBLANK(AL14)), "", AL14*AK14) | AP14: FALSE | AQ14: =IF(ISBLANK(AO14), "", IF(AP14, AO14, AO14*$F14 ) ) | AR14: =IF(ISBLANK(AN14), 0, VLOOKUP(AN14, 'Price Sheet'!$A$2:$B1015, 2, false)) -> 0 | AS14: =IF(OR(ISBLANK(AO14), ISBLANK(AR14)), "", AR14*AQ14) | AV14: FALSE | AW14: =IF(ISBLANK(AU14), "", IF(AV14, AU14, AU14*$F14 ) ) | AX14: =IF(ISBLANK(AT14), 0, VLOOKUP(AT14, 'Price Sheet'!$A$2:$B1015, 2, false)) -> 0 | AY14: =IF(OR(ISBLANK(AU14), ISBLANK(AX14)), "", AX14*AW14) | BB14: FALSE | BC14: =IF(ISBLANK(BA14), "", IF(BB14, BA14, BA14*$F14 ) ) | BD14: =IF(ISBLANK(AZ14), 0, VLOOKUP(AZ14, 'Price Sheet'!$A$2:$B1015, 2, false)) -> 0 | BE14: =IF(OR(ISBLANK(BA14), ISBLANK(BD14)), "", BD14*BC14) | BH14: FALSE | BI14: =IF(ISBLANK(BG14), "", IF(BH14, BG14, BG14*$F14 ) ) | BJ14: =IF(ISBLANK(BF14), 0, VLOOKUP(BF14, 'Price Sheet'!$A$2:$B1015, 2, false)) -> 0 | BK14: =IF(OR(ISBLANK(BG14), ISBLANK(BJ14)), "", BJ14*BI14) | BN14: FALSE | BO14: =IF(ISBLANK(BM14), "", IF(BN14, BM14, BM14*$F14 ) ) | BP14: =IF(ISBLANK(BL14), 0, VLOOKUP(BL14, 'Price Sheet'!$A$2:$B1015, 2, false)) -> 0 | BQ14: =IF(OR(ISBLANK(BM14), ISBLANK(BP14)), "", BP14*BO14)
